Workbook

Sheet moderate_hydrogen_high_ccs
A1: Vintage | B1: Battery_Storage | C1: Battery_Storage_energy | D1: Central_PV | E1: Residential_PV | F1: Gas_Combustion_Turbine | G1: Gas_Combustion_Turbine_CCS | H1: Gas_CCGT | I1: Gas_CCGT_CCS | J1: Wind | K1: Offshore_Wind | L1: Coal | M1: Coal_CCS | N1: Coal_IGCC | O1: Coal_IGCC_CCS | P1: Nuclear | Q1: Hydro_Pumped | R1: Hydro_NonPumped | S1: SMR | T1: SMR_CCS | U1: Gasification | V1: Gasification_CCS | W1: Electrolyzer | X1: Fuel_cell | Y1: Hydrogen_turbine | Z1: Tank | AA1: Salt_cavern | AB1: CCS_storage_oil | AC1: CCS_storage_saline | AD1: CCS_storage_offshore | AE1: DAC
A2: 2020 | B2: =OFFSET(battery!$F$15,(ROW(B1)-1)*5,0)*1000 -> 492307.69 | C2: =OFFSET(battery!$C$15,(ROW(C1)-1)*5,0)*1000 -> 246153.85 | D2: =OFFSET(Solar!$C$11,(ROW(D1)-1)*5,0)*1000 -> 628000 | E2: =OFFSET(Solar!$F$11,(ROW(Solar!E1)-1)*5,0)*1000 -> 746000 | F2: =OFFSET(gas!$C$18,(ROW(gas!C1)-1)*5,0)*1000 -> 367230.77 | G2: =ccs!$H$6*ccs!$B$20*8760 -> 2957746.1 | H2: =OFFSET(gas!$F$18,(ROW(gas!E1)-1)*5,0)*1000 -> 408913.26 | I2: =ccs!$H$6*ccs!$B$20*8760 -> 2957746.1 | J2: =OFFSET(land!$C$12,(ROW(J1)-1)*5,0)*1000 -> 1157000 | K2: =OFFSET(offshore!$K$13,(ROW(K1)-1)*5,0)*1000 -> 2857000 | L2: =OFFSET(coal!$C$20,(ROW(L1)-1)*5,0)*1000 -> 622461.54 | M2: =ccs!$C$6*ccs!$B$20*8760 -> 3086497.8 | N2: =OFFSET(coal!$F$20,(ROW(N1)-1)*5,0)*1000 -> 1089999.5 | O2: =ccs!$F$6*ccs!$B$20*8760 -> 2342606.6 | P2: =OFFSET(nuclear!$B$8,(ROW(P1)-1)*5,0)*1000 -> 2461538.5 | Q2: =5969/6.5*1000 -> 918307.69 | R2: =2240.15384615385*1000 -> 2240153.8 | S2: =SMR!T2 -> 546556.72 | T2: =ccs!$J$6*ccs!B$20*8760 -> 769681.35 | U2: =SMR!V2 -> 3272268.8 | V2: =ccs!$J$6*ccs!B$20*8760 -> 769681.35 | W2: =OFFSET(Electrolyzer!$C$2,(ROW(W1)-1)*5,0)*1000 -> 1245090 | X2: ='Fuel cell'!C2*1000 -> 1562022 | Y2: =OFFSET('H2 turbine'!$B$12,(ROW(Z1)-1)*5,0)*1000 -> 314777.78 | Z2: ='hydrogen storage'!B9 -> 69045.9 | AA2: ='hydrogen storage'!D9 -> 3610.761 | AB2: =2.36*1.1*1.0928 -> 2.8369088 | AC2: =AB2*2 -> 5.6738176 | AD2: =3.89*1.1*1.0928 -> 4.6760912 | AE2: =DAC!$B$19*8760 -> 7357350
A3: 2025 | B3: =OFFSET(battery!$F$15,(ROW(B2)-1)*5,0)*1000 -> 474606.98 | C3: =OFFSET(battery!$C$15,(ROW(C2)-1)*5,0)*1000 -> 219340.56 | D3: =OFFSET(Solar!$C$11,(ROW(D2)-1)*5,0)*1000 -> 607009.58 | E3: =OFFSET(Solar!$F$11,(ROW(Solar!E2)-1)*5,0)*1000 -> 686543.83 | F3: =OFFSET(gas!$C$18,(ROW(gas!C2)-1)*5,0)*1000 -> 358513.34 | G3: =ccs!$H$6*ccs!$B$20*8760 -> 2957746.1 | H3: =OFFSET(gas!$F$18,(ROW(gas!E2)-1)*5,0)*1000 -> 398327.81 | I3: =ccs!$H$6*ccs!$B$20*8760 -> 2957746.1 | J3: =OFFSET(land!$C$12,(ROW(J2)-1)*5,0)*1000 -> 1076641 | K3: =OFFSET(offshore!$K$13,(ROW(K2)-1)*5,0)*1000 -> 2492044 | L3: =OFFSET(coal!$C$20,(ROW(L2)-1)*5,0)*1000 -> 612285.83 | M3: =ccs!$C$6*ccs!$B$20*8760 -> 3086497.8 | N3: =OFFSET(coal!$F$20,(ROW(N2)-1)*5,0)*1000 -> 1083549.8 | O3: =ccs!$F$6*ccs!$B$20*8760 -> 2342606.6 | P3: =OFFSET(nuclear!$B$8,(ROW(P2)-1)*5,0)*1000 -> 2113664.3 | Q3: =5969/6.5*1000 -> 918307.69 | R3: =2240.15384615385*1000 -> 2240153.8 | S3: =SMR!T3 -> 533582.41 | T3: =ccs!$J$6*ccs!B$20*8760 -> 769681.35 | U3: =SMR!V3 -> 3218775.3 | V3: =ccs!$J$6*ccs!B$20*8760 -> 769681.35 | W3: =OFFSET(Electrolyzer!$C$2,(ROW(W2)-1)*5,0)*1000 -> 905520 | X3: ='Fuel cell'!C3*1000 -> 1443172.5 | Y3: =OFFSET('H2 turbine'!$B$12,(ROW(Z2)-1)*5,0)*1000 -> 313166.67 | Z3: ='hydrogen storage'!B10 -> 61688.55 | AA3: ='hydrogen storage'!D10 -> 3010.854 | AB3: =2.36*1.1*1.0928 -> 2.8369088 | AC3: =AB3*2 -> 5.6738176 | AD3: =3.89*1.1*1.0928 -> 4.6760912 | AE3: =DAC!$B$19*8760 -> 7357350
A4: 2030 | B4: =OFFSET(battery!$F$15,(ROW(B3)-1)*5,0)*1000 -> 483790.42 | C4: =OFFSET(battery!$C$15,(ROW(C3)-1)*5,0)*1000 -> 173879.95 | D4: =OFFSET(Solar!$C$11,(ROW(D3)-1)*5,0)*1000 -> 505217.02 | E4: =OFFSET(Solar!$F$11,(ROW(Solar!E3)-1)*5,0)*1000 -> 548996.6 | F4: =OFFSET(gas!$C$18,(ROW(gas!C3)-1)*5,0)*1000 -> 344008.72 | G4: =ccs!$H$6*ccs!$B$20*8760 -> 2957746.1 | H4: =OFFSET(gas!$F$18,(ROW(gas!E3)-1)*5,0)*1000 -> 380673.19 | I4: =ccs!$H$6*ccs!$B$20*8760 -> 2957746.1 | J4: =OFFSET(land!$C$12,(ROW(J3)-1)*5,0)*1000 -> 976192.22 | K4: =OFFSET(offshore!$K$13,(ROW(K3)-1)*5,0)*1000 -> 2290687.3 | L4: =OFFSET(coal!$C$20,(ROW(L3)-1)*5,0)*1000 -> 595355.36 | M4: =ccs!$C$6*ccs!$B$20*8760 -> 3086497.8 | N4: =OFFSET(coal!$F$20,(ROW(N3)-1)*5,0)*1000 -> 1072807.6 | O4: =ccs!$F$6*ccs!$B$20*8760 -> 2342606.6 | P4: =OFFSET(nuclear!$B$8,(ROW(P3)-1)*5,0)*1000 -> 2015508 | Q4: =5969/6.5*1000 -> 918307.69 | R4: =2240.15384615385*1000 -> 2240153.8 | S4: =SMR!T4 -> 511994.89 | T4: =ccs!$J$6*ccs!B$20*8760 -> 769681.35 | U4: =SMR!V4 -> 3129772.1 | V4: =ccs!$J$6*ccs!B$20*8760 -> 769681.35 | W4: =OFFSET(Electrolyzer!$C$2,(ROW(W3)-1)*5,0)*1000 -> 565950 | X4: ='Fuel cell'!C4*1000 -> 1324323 | Y4: =OFFSET('H2 turbine'!$B$12,(ROW(Z3)-1)*5,0)*1000 -> 311555.56 | Z4: ='hydrogen storage'!B11 -> 54331.2 | AA4: ='hydrogen storage'!D11 -> 2410.947 | AB4: =2.36*1.1*1.0928 -> 2.8369088 | AC4: =AB4*2 -> 5.6738176 | AD4: =3.89*1.1*1.0928 -> 4.6760912 | AE4: =DAC!$B$19*8760 -> 7357350
A5: 2035 | B5: =OFFSET(battery!$F$15,(ROW(B4)-1)*5,0)*1000 -> 467109.57 | C5: =OFFSET(battery!$C$15,(ROW(C4)-1)*5,0)*1000 -> 158078 | D5: =OFFSET(Solar!$C$11,(ROW(D4)-1)*5,0)*1000 -> 403424.47 | E5: =OFFSET(Solar!$F$11,(ROW(Solar!E4)-1)*5,0)*1000 -> 411449.37 | F5: =OFFSET(gas!$C$18,(ROW(gas!C4)-1)*5,0)*1000 -> 329504.09 | G5: =ccs!$H$6*ccs!$B$20*8760 -> 2957746.1 | H5: =OFFSET(gas!$F$18,(ROW(gas!E4)-1)*5,0)*1000 -> 363018.57 | I5: =ccs!$H$6*ccs!$B$20*8760 -> 2957746.1 | J5: =OFFSET(land!$C$12,(ROW(J4)-1)*5,0)*1000 -> 928132.19 | K5: =OFFSET(offshore!$K$13,(ROW(K4)-1)*5,0)*1000 -> 2166215.1 | L5: =OFFSET(coal!$C$20,(ROW(L4)-1)*5,0)*1000 -> 578403.11 | M5: =ccs!$C$6*ccs!$B$20*8760 -> 3086497.8 | N5: =OFFSET(coal!$F$20,(ROW(N4)-1)*5,0)*1000 -> 1062087.1 | O5: =ccs!$F$6*ccs!$B$20*8760 -> 2342606.6 | P5: =OFFSET(nuclear!$B$8,(ROW(P4)-1)*5,0)*1000 -> 1948571.2 | Q5: =5969/6.5*1000 -> 918307.69 | R5: =2240.15384615385*1000 -> 2240153.8 | S5: =SMR!T5 -> 490407.37 | T5: =ccs!$J$6*ccs!B$20*8760 -> 769681.35 | U5: =SMR!V5 -> 3040654.4 | V5: =ccs!$J$6*ccs!B$20*8760 -> 769681.35 | W5: =OFFSET(Electrolyzer!$C$2,(ROW(W4)-1)*5,0)*1000 -> 694166.67 | X5: ='Fuel cell'!C5*1000 -> 1233771 | Y5: =OFFSET('H2 turbine'!$B$12,(ROW(Z4)-1)*5,0)*1000 -> 309944.44 | Z5: ='hydrogen storage'!B12 -> 43578.15 | AA5: ='hydrogen storage'!D12 -> 2110.9935 | AB5: =2.36*1.1*1.0928 -> 2.8369088 | AC5: =AB5*2 -> 5.6738176 | AD5: =3.89*1.1*1.0928 -> 4.6760912 | AE5: =DAC!$B$19*8760 -> 7357350
A6: 2040 | B6: =OFFSET(battery!$F$15,(ROW(B5)-1)*5,0)*1000 -> 449709.83 | C6: =OFFSET(battery!$C$15,(ROW(C5)-1)*5,0)*1000 -> 142362.74 | D6: =OFFSET(Solar!$C$11,(ROW(D5)-1)*5,0)*1000 -> 371518.84 | E6: =OFFSET(Solar!$F$11,(ROW(Solar!E5)-1)*5,0)*1000 -> 371597.4 | F6: =OFFSET(gas!$C$18,(ROW(gas!C5)-1)*5,0)*1000 -> 314962.84 | G6: =ccs!$H$6*ccs!$B$20*8760 -> 2957746.1 | H6: =OFFSET(gas!$F$18,(ROW(gas!E5)-1)*5,0)*1000 -> 348074.41 | I6: =ccs!$H$6*ccs!$B$20*8760 -> 2957746.1 | J6: =OFFSET(land!$C$12,(ROW(J5)-1)*5,0)*1000 -> 880072.15 | K6: =OFFSET(offshore!$K$13,(ROW(K5)-1)*5,0)*1000 -> 2075879.5 | L6: =OFFSET(coal!$C$20,(ROW(L5)-1)*5,0)*1000 -> 550665.03 | M6: =ccs!$C$6*ccs!$B$20*8760 -> 3086497.8 | N6: =OFFSET(coal!$F$20,(ROW(N5)-1)*5,0)*1000 -> 1051344.9 | O6: =ccs!$F$6*ccs!$B$20*8760 -> 2342606.6 | P6: =OFFSET(nuclear!$B$8,(ROW(P5)-1)*5,0)*1000 -> 1879782.7 | Q6: =5969/6.5*1000 -> 918307.69 | R6: =2240.15384615385*1000 -> 2240153.8 | S6: =SMR!T6 -> 468765.34 | T6: =ccs!$J$6*ccs!B$20*8760 -> 769681.35 | U6: =SMR!V6 -> 2894835.9 | V6: =ccs!$J$6*ccs!B$20*8760 -> 769681.35 | W6: =OFFSET(Electrolyzer!$C$2,(ROW(W5)-1)*5,0)*1000 -> 452760 | X6: ='Fuel cell'!C6*1000 -> 1143219 | Y6: =OFFSET('H2 turbine'!$B$12,(ROW(Z5)-1)*5,0)*1000 -> 308333.33 | Z6: ='hydrogen storage'!B13 -> 32825.1 | AA6: ='hydrogen storage'!D13 -> 1811.04 | AB6: =2.36*1.1*1.0928 -> 2.8369088 | AC6: =AB6*2 -> 5.6738176 | AD6: =3.89*1.1*1.0928 -> 4.6760912 | AE6: =DAC!$B$19*8760 -> 7357350
A7: 2045 | B7: =OFFSET(battery!$F$15,(ROW(B6)-1)*5,0)*1000 -> 431425.3 | C7: =OFFSET(battery!$C$15,(ROW(C6)-1)*5,0)*1000 -> 126754.17 | D7: =OFFSET(Solar!$C$11,(ROW(D6)-1)*5,0)*1000 -> 339613.21 | E7: =OFFSET(Solar!$F$11,(ROW(Solar!E6)-1)*5,0)*1000 -> 331745.43 | F7: =OFFSET(gas!$C$18,(ROW(gas!C6)-1)*5,0)*1000 -> 300458.21 | G7: =ccs!$H$6*ccs!$B$20*8760 -> 2957746.1 | H7: =OFFSET(gas!$F$18,(ROW(gas!E6)-1)*5,0)*1000 -> 333130.25 | I7: =ccs!$H$6*ccs!$B$20*8760 -> 2957746.1 | J7: =OFFSET(land!$C$12,(ROW(J6)-1)*5,0)*1000 -> 832012.11 | K7: =OFFSET(offshore!$K$13,(ROW(K6)-1)*5,0)*1000 -> 2004930.7 | L7: =OFFSET(coal!$C$20,(ROW(L6)-1)*5,0)*1000 -> 522948.75 | M7: =ccs!$C$6*ccs!$B$20*8760 -> 3086497.8 | N7: =OFFSET(coal!$F$20,(ROW(N6)-1)*5,0)*1000 -> 1040624.4 | O7: =ccs!$F$6*ccs!$B$20*8760 -> 2342606.6 | P7: =OFFSET(nuclear!$B$8,(ROW(P6)-1)*5,0)*1000 -> 1815208.1 | Q7: =5969/6.5*1000 -> 918307.69 | R7: =2240.15384615385*1000 -> 2240153.8 | S7: =SMR!T7 -> 447177.82 | T7: =ccs!$J$6*ccs!B$20*8760 -> 769681.35 | U7: =SMR!V7 -> 2749131.9 | V7: =ccs!$J$6*ccs!B$20*8760 -> 769681.35 | W7: =OFFSET(Electrolyzer!$C$2,(ROW(W6)-1)*5,0)*1000 -> 639833.33 | X7: ='Fuel cell'!C7*1000 -> 1052667 | Y7: =OFFSET('H2 turbine'!$B$12,(ROW(Z6)-1)*5,0)*1000 -> 306722.22 | Z7: ='hydrogen storage'!B14 -> 28863.45 | AA7: ='hydrogen storage'!D14 -> 1629.936 | AB7: =2.36*1.1*1.0928 -> 2.8369088 | AC7: =AB7*2 -> 5.6738176 | AD7: =3.89*1.1*1.0928 -> 4.6760912 | AE7: =DAC!$B$19*8760 -> 7357350
A8: 2050 | B8: =OFFSET(battery!$F$15,(ROW(B7)-1)*5,0)*1000 -> 412034.81 | C8: =OFFSET(battery!$C$15,(ROW(C7)-1)*5,0)*1000 -> 111278.96 | D8: =OFFSET(Solar!$C$11,(ROW(D7)-1)*5,0)*1000 -> 307707.58 | E8: =OFFSET(Solar!$F$11,(ROW(Solar!E7)-1)*5,0)*1000 -> 291893.46 | F8: =OFFSET(gas!$C$18,(ROW(gas!C7)-1)*5,0)*1000 -> 285953.58 | G8: =ccs!$H$6*ccs!$B$20*8760 -> 2957746.1 | H8: =OFFSET(gas!$F$18,(ROW(gas!E7)-1)*5,0)*1000 -> 318222.71 | I8: =ccs!$H$6*ccs!$B$20*8760 -> 2957746.1 | J8: =OFFSET(land!$C$12,(ROW(J7)-1)*5,0)*1000 -> 783952.07 | K8: =OFFSET(offshore!$K$13,(ROW(K7)-1)*5,0)*1000 -> 1946500.3 | L8: =OFFSET(coal!$C$20,(ROW(L7)-1)*5,0)*1000 -> 495210.68 | M8: =ccs!$C$6*ccs!$B$20*8760 -> 3086497.8 | N8: =OFFSET(coal!$F$20,(ROW(N7)-1)*5,0)*1000 -> 1029882.2 | O8: =ccs!$F$6*ccs!$B$20*8760 -> 2342606.6 | P8: =OFFSET(nuclear!$B$8,(ROW(P7)-1)*5,0)*1000 -> 1738729.6 | Q8: =5969/6.5*1000 -> 918307.69 | R8: =2240.15384615385*1000 -> 2240153.8 | S8: =SMR!T8 -> 425590.3 | T8: =ccs!$J$6*ccs!B$20*8760 -> 769681.35 | U8: =SMR!V8 -> 2603313.4 | V8: =ccs!$J$6*ccs!B$20*8760 -> 769681.35 | W8: =OFFSET(Electrolyzer!$C$2,(ROW(W7)-1)*5,0)*1000 -> 311272.5 | X8: ='Fuel cell'!C8*1000 -> 962115 | Y8: =OFFSET('H2 turbine'!$B$12,(ROW(Z7)-1)*5,0)*1000 -> 305111.11 | Z8: ='hydrogen storage'!B15 -> 24901.8 | AA8: ='hydrogen storage'!D15 -> 1448.832 | AB8: =2.36*1.1*1.0928 -> 2.8369088 | AC8: =AB8*2 -> 5.6738176 | AD8: =3.89*1.1*1.0928 -> 4.6760912 | AE8: =DAC!$B$19*8760 -> 7357350

Sheet moderate_hydrogen
A1: Vintage | B1: Battery_Storage | C1: Battery_Storage_energy | D1: Central_PV | E1: Residential_PV | F1: Gas_Combustion_Turbine | G1: Gas_Combustion_Turbine_CCS | H1: Gas_CCGT | I1: Gas_CCGT_CCS | J1: Wind | K1: Offshore_Wind | L1: Coal | M1: Coal_CCS | N1: Coal_IGCC | O1: Coal_IGCC_CCS | P1: Nuclear | Q1: Hydro_Pumped | R1: Hydro_NonPumped | S1: SMR | T1: SMR_CCS | U1: Gasification | V1: Gasification_CCS | W1: Electrolyzer | X1: Fuel_cell | Y1: Hydrogen_turbine | Z1: Tank | AA1: Salt_cavern | AB1: CCS_storage_oil | AC1: CCS_storage_saline | AD1: CCS_storage_offshore | AE1: DAC
A2: 2020 | B2: =OFFSET(battery!$F$15,(ROW(B1)-1)*5,0)*1000 -> 492307.69 | C2: =OFFSET(battery!$C$15,(ROW(C1)-1)*5,0)*1000 -> 246153.85 | D2: =OFFSET(Solar!$C$11,(ROW(D1)-1)*5,0)*1000 -> 628000 | E2: =OFFSET(Solar!$F$11,(ROW(Solar!E1)-1)*5,0)*1000 -> 746000 | F2: =OFFSET(gas!$C$18,(ROW(gas!C1)-1)*5,0)*1000 -> 367230.77 | G2: =ccs!$H$6*ccs!B20*8760 -> 2957746.1 | H2: =OFFSET(gas!$F$18,(ROW(gas!E1)-1)*5,0)*1000 -> 408913.26 | I2: =ccs!$H$6*ccs!B20*8760 -> 2957746.1 | J2: =OFFSET(land!$C$12,(ROW(J1)-1)*5,0)*1000 -> 1157000 | K2: =OFFSET(offshore!$K$13,(ROW(K1)-1)*5,0)*1000 -> 2857000 | L2: =OFFSET(coal!$C$20,(ROW(L1)-1)*5,0)*1000 -> 622461.54 | M2: =ccs!$C$6*ccs!B20*8760 -> 3086497.8 | N2: =OFFSET(coal!$F$20,(ROW(N1)-1)*5,0)*1000 -> 1089999.5 | O2: =ccs!$F$6*ccs!B20*8760 -> 2342606.6 | P2: =OFFSET(nuclear!$B$8,(ROW(P1)-1)*5,0)*1000 -> 2461538.5 | Q2: =5969/6.5*1000 -> 918307.69 | R2: =2240.15384615385*1000 -> 2240153.8 | S2: =SMR!T2 -> 546556.72 | T2: =ccs!$J$6*ccs!B20*8760 -> 769681.35 | U2: =SMR!V2 -> 3272268.8 | V2: =ccs!$J$6*ccs!B20*8760 -> 769681.35 | W2: =OFFSET(Electrolyzer!$C$2,(ROW(W1)-1)*5,0)*1000 -> 1245090 | X2: ='Fuel cell'!C2*1000 -> 1562022 | Y2: =OFFSET('H2 turbine'!$B$12,(ROW(Z1)-1)*5,0)*1000 -> 314777.78 | Z2: ='hydrogen storage'!B9 -> 69045.9 | AA2: ='hydrogen storage'!D9 -> 3610.761 | AB2: =2.36*1.1*1.0928 -> 2.8369088 | AC2: =AB2*2 -> 5.6738176 | AD2: =3.89*1.1*1.0928 -> 4.6760912 | AE2: =DAC!B19*8760 -> 7357350
A3: 2025 | B3: =OFFSET(battery!$F$15,(ROW(B2)-1)*5,0)*1000 -> 474606.98 | C3: =OFFSET(battery!$C$15,(ROW(C2)-1)*5,0)*1000 -> 219340.56 | D3: =OFFSET(Solar!$C$11,(ROW(D2)-1)*5,0)*1000 -> 607009.58 | E3: =OFFSET(Solar!$F$11,(ROW(Solar!E2)-1)*5,0)*1000 -> 686543.83 | F3: =OFFSET(gas!$C$18,(ROW(gas!C2)-1)*5,0)*1000 -> 358513.34 | G3: =ccs!$H$6*ccs!B21*8760 -> 2063543.8 | H3: =OFFSET(gas!$F$18,(ROW(gas!E2)-1)*5,0)*1000 -> 398327.81 | I3: =ccs!$H$6*ccs!B21*8760 -> 2063543.8 | J3: =OFFSET(land!$C$12,(ROW(J2)-1)*5,0)*1000 -> 1076641 | K3: =OFFSET(offshore!$K$13,(ROW(K2)-1)*5,0)*1000 -> 2492044 | L3: =OFFSET(coal!$C$20,(ROW(L2)-1)*5,0)*1000 -> 612285.83 | M3: =ccs!$C$6*ccs!B21*8760 -> 2153370.6 | N3: =OFFSET(coal!$F$20,(ROW(N2)-1)*5,0)*1000 -> 1083549.8 | O3: =ccs!$F$6*ccs!B21*8760 -> 1634376.7 | P3: =OFFSET(nuclear!$B$8,(ROW(P2)-1)*5,0)*1000 -> 2113664.3 | Q3: =5969/6.5*1000 -> 918307.69 | R3: =2240.15384615385*1000 -> 2240153.8 | S3: =SMR!T3 -> 533582.41 | T3: =ccs!$J$6*ccs!B21*8760 -> 536986.99 | U3: =SMR!V3 -> 3218775.3 | V3: =ccs!$J$6*ccs!B21*8760 -> 536986.99 | W3: =OFFSET(Electrolyzer!$C$2,(ROW(W2)-1)*5,0)*1000 -> 905520 | X3: ='Fuel cell'!C3*1000 -> 1443172.5 | Y3: =OFFSET('H2 turbine'!$B$12,(ROW(Z2)-1)*5,0)*1000 -> 313166.67 | Z3: ='hydrogen storage'!B10 -> 61688.55 | AA3: ='hydrogen storage'!D10 -> 3010.854 | AB3: =2.25*1.1*1.0928 -> 2.70468 | AC3: =AB3*2 -> 5.40936 | AD3: =3.7*1.1*1.0928 -> 4.447696 | AE3: =DAC!B20*8760 -> 5433120
A4: 2030 | B4: =OFFSET(battery!$F$15,(ROW(B3)-1)*5,0)*1000 -> 483790.42 | C4: =OFFSET(battery!$C$15,(ROW(C3)-1)*5,0)*1000 -> 173879.95 | D4: =OFFSET(Solar!$C$11,(ROW(D3)-1)*5,0)*1000 -> 505217.02 | E4: =OFFSET(Solar!$F$11,(ROW(Solar!E3)-1)*5,0)*1000 -> 548996.6 | F4: =OFFSET(gas!$C$18,(ROW(gas!C3)-1)*5,0)*1000 -> 344008.72 | G4: =ccs!$H$6*ccs!B22*8760 -> 1719619.8 | H4: =OFFSET(gas!$F$18,(ROW(gas!E3)-1)*5,0)*1000 -> 380673.19 | I4: =ccs!$H$6*ccs!B22*8760 -> 1719619.8 | J4: =OFFSET(land!$C$12,(ROW(J3)-1)*5,0)*1000 -> 976192.22 | K4: =OFFSET(offshore!$K$13,(ROW(K3)-1)*5,0)*1000 -> 2290687.3 | L4: =OFFSET(coal!$C$20,(ROW(L3)-1)*5,0)*1000 -> 595355.36 | M4: =ccs!$C$6*ccs!B22*8760 -> 1794475.5 | N4: =OFFSET(coal!$F$20,(ROW(N3)-1)*5,0)*1000 -> 1072807.6 | O4: =ccs!$F$6*ccs!B22*8760 -> 1361980.6 | P4: =OFFSET(nuclear!$B$8,(ROW(P3)-1)*5,0)*1000 -> 2015508 | Q4: =5969/6.5*1000 -> 918307.69 | R4: =2240.15384615385*1000 -> 2240153.8 | S4: =SMR!T4 -> 511994.89 | T4: =ccs!$J$6*ccs!B22*8760 -> 447489.16 | U4: =SMR!V4 -> 3129772.1 | V4: =ccs!$J$6*ccs!B22*8760 -> 447489.16 | W4: =OFFSET(Electrolyzer!$C$2,(ROW(W3)-1)*5,0)*1000 -> 565950 | X4: ='Fuel cell'!C4*1000 -> 1324323 | Y4: =OFFSET('H2 turbine'!$B$12,(ROW(Z3)-1)*5,0)*1000 -> 311555.56 | Z4: ='hydrogen storage'!B11 -> 54331.2 | AA4: ='hydrogen storage'!D11 -> 2410.947 | AB4: =2.14*1.1*1.0928 -> 2.5724512 | AC4: =AB4*2 -> 5.1449024 | AD4: =3.52*1.1*1.0928 -> 4.2313216 | AE4: =DAC!B21*8760 -> 3395700
A5: 2035 | B5: =OFFSET(battery!$F$15,(ROW(B4)-1)*5,0)*1000 -> 467109.57 | C5: =OFFSET(battery!$C$15,(ROW(C4)-1)*5,0)*1000 -> 158078 | D5: =OFFSET(Solar!$C$11,(ROW(D4)-1)*5,0)*1000 -> 403424.47 | E5: =OFFSET(Solar!$F$11,(ROW(Solar!E4)-1)*5,0)*1000 -> 411449.37 | F5: =OFFSET(gas!$C$18,(ROW(gas!C4)-1)*5,0)*1000 -> 329504.09 | G5: =ccs!$H$6*ccs!B23*8760 -> 1582050.2 | H5: =OFFSET(gas!$F$18,(ROW(gas!E4)-1)*5,0)*1000 -> 363018.57 | I5: =ccs!$H$6*ccs!B23*8760 -> 1582050.2 | J5: =OFFSET(land!$C$12,(ROW(J4)-1)*5,0)*1000 -> 928132.19 | K5: =OFFSET(offshore!$K$13,(ROW(K4)-1)*5,0)*1000 -> 2166215.1 | L5: =OFFSET(coal!$C$20,(ROW(L4)-1)*5,0)*1000 -> 578403.11 | M5: =ccs!$C$6*ccs!B23*8760 -> 1650917.4 | N5: =OFFSET(coal!$F$20,(ROW(N4)-1)*5,0)*1000 -> 1062087.1 | O5: =ccs!$F$6*ccs!B23*8760 -> 1253022.1 | P5: =OFFSET(nuclear!$B$8,(ROW(P4)-1)*5,0)*1000 -> 1948571.2 | Q5: =5969/6.5*1000 -> 918307.69 | R5: =2240.15384615385*1000 -> 2240153.8 | S5: =SMR!T5 -> 490407.37 | T5: =ccs!$J$6*ccs!B23*8760 -> 411690.02 | U5: =SMR!V5 -> 3040654.4 | V5: =ccs!$J$6*ccs!B23*8760 -> 411690.02 | W5: =OFFSET(Electrolyzer!$C$2,(ROW(W4)-1)*5,0)*1000 -> 694166.67 | X5: ='Fuel cell'!C5*1000 -> 1233771 | Y5: =OFFSET('H2 turbine'!$B$12,(ROW(Z4)-1)*5,0)*1000 -> 309944.44 | Z5: ='hydrogen storage'!B12 -> 43578.15 | AA5: ='hydrogen storage'!D12 -> 2110.9935 | AB5: =(AB4+AB6)/2 -> 2.4462328 | AC5: =AB5*2 -> 4.8924656 | AD5: =(AD4+AD6)/2 -> 4.026968 | AE5: =DAC!B22*8760 -> 2886345
A6: 2040 | B6: =OFFSET(battery!$F$15,(ROW(B5)-1)*5,0)*1000 -> 449709.83 | C6: =OFFSET(battery!$C$15,(ROW(C5)-1)*5,0)*1000 -> 142362.74 | D6: =OFFSET(Solar!$C$11,(ROW(D5)-1)*5,0)*1000 -> 371518.84 | E6: =OFFSET(Solar!$F$11,(ROW(Solar!E5)-1)*5,0)*1000 -> 371597.4 | F6: =OFFSET(gas!$C$18,(ROW(gas!C5)-1)*5,0)*1000 -> 314962.84 | G6: =ccs!$H$6*ccs!B24*8760 -> 1444480.6 | H6: =OFFSET(gas!$F$18,(ROW(gas!E5)-1)*5,0)*1000 -> 348074.41 | I6: =ccs!$H$6*ccs!B24*8760 -> 1444480.6 | J6: =OFFSET(land!$C$12,(ROW(J5)-1)*5,0)*1000 -> 880072.15 | K6: =OFFSET(offshore!$K$13,(ROW(K5)-1)*5,0)*1000 -> 2075879.5 | L6: =OFFSET(coal!$C$20,(ROW(L5)-1)*5,0)*1000 -> 550665.03 | M6: =ccs!$C$6*ccs!B24*8760 -> 1507359.4 | N6: =OFFSET(coal!$F$20,(ROW(N5)-1)*5,0)*1000 -> 1051344.9 | O6: =ccs!$F$6*ccs!B24*8760 -> 1144063.7 | P6: =OFFSET(nuclear!$B$8,(ROW(P5)-1)*5,0)*1000 -> 1879782.7 | Q6: =5969/6.5*1000 -> 918307.69 | R6: =2240.15384615385*1000 -> 2240153.8 | S6: =SMR!T6 -> 468765.34 | T6: =ccs!$J$6*ccs!B24*8760 -> 375890.89 | U6: =SMR!V6 -> 2894835.9 | V6: =ccs!$J$6*ccs!B24*8760 -> 375890.89 | W6: =OFFSET(Electrolyzer!$C$2,(ROW(W5)-1)*5,0)*1000 -> 452760 | X6: ='Fuel cell'!C6*1000 -> 1143219 | Y6: =OFFSET('H2 turbine'!$B$12,(ROW(Z5)-1)*5,0)*1000 -> 308333.33 | Z6: ='hydrogen storage'!B13 -> 32825.1 | AA6: ='hydrogen storage'!D13 -> 1811.04 | AB6: =1.93*1.1*1.0928 -> 2.3200144 | AC6: =AB6*2 -> 4.6400288 | AD6: =3.18*1.1*1.0928 -> 3.8226144 | AE6: =DAC!B23*8760 -> 2376990
A7: 2045 | B7: =OFFSET(battery!$F$15,(ROW(B6)-1)*5,0)*1000 -> 431425.3 | C7: =OFFSET(battery!$C$15,(ROW(C6)-1)*5,0)*1000 -> 126754.17 | D7: =OFFSET(Solar!$C$11,(ROW(D6)-1)*5,0)*1000 -> 339613.21 | E7: =OFFSET(Solar!$F$11,(ROW(Solar!E6)-1)*5,0)*1000 -> 331745.43 | F7: =OFFSET(gas!$C$18,(ROW(gas!C6)-1)*5,0)*1000 -> 300458.21 | G7: =ccs!$H$6*ccs!B25*8760 -> 1410088.2 | H7: =OFFSET(gas!$F$18,(ROW(gas!E6)-1)*5,0)*1000 -> 333130.25 | I7: =ccs!$H$6*ccs!B25*8760 -> 1410088.2 | J7: =OFFSET(land!$C$12,(ROW(J6)-1)*5,0)*1000 -> 832012.11 | K7: =OFFSET(offshore!$K$13,(ROW(K6)-1)*5,0)*1000 -> 2004930.7 | L7: =OFFSET(coal!$C$20,(ROW(L6)-1)*5,0)*1000 -> 522948.75 | M7: =ccs!$C$6*ccs!B25*8760 -> 1471469.9 | N7: =OFFSET(coal!$F$20,(ROW(N6)-1)*5,0)*1000 -> 1040624.4 | O7: =ccs!$F$6*ccs!B25*8760 -> 1116824.1 | P7: =OFFSET(nuclear!$B$8,(ROW(P6)-1)*5,0)*1000 -> 1815208.1 | Q7: =5969/6.5*1000 -> 918307.69 | R7: =2240.15384615385*1000 -> 2240153.8 | S7: =SMR!T7 -> 447177.82 | T7: =ccs!$J$6*ccs!B25*8760 -> 366941.11 | U7: =SMR!V7 -> 2749131.9 | V7: =ccs!$J$6*ccs!B25*8760 -> 366941.11 | W7: =OFFSET(Electrolyzer!$C$2,(ROW(W6)-1)*5,0)*1000 -> 639833.33 | X7: ='Fuel cell'!C7*1000 -> 1052667 | Y7: =OFFSET('H2 turbine'!$B$12,(ROW(Z6)-1)*5,0)*1000 -> 306722.22 | Z7: ='hydrogen storage'!B14 -> 28863.45 | AA7: ='hydrogen storage'!D14 -> 1629.936 | AB7: =1.93*1.1*1.0928 -> 2.3200144 | AC7: =AB7*2 -> 4.6400288 | AD7: =3.18*1.1*1.0928 -> 3.8226144 | AE7: =DAC!B24*8760 -> 2207205
A8: 2050 | B8: =OFFSET(battery!$F$15,(ROW(B7)-1)*5,0)*1000 -> 412034.81 | C8: =OFFSET(battery!$C$15,(ROW(C7)-1)*5,0)*1000 -> 111278.96 | D8: =OFFSET(Solar!$C$11,(ROW(D7)-1)*5,0)*1000 -> 307707.58 | E8: =OFFSET(Solar!$F$11,(ROW(Solar!E7)-1)*5,0)*1000 -> 291893.46 | F8: =OFFSET(gas!$C$18,(ROW(gas!C7)-1)*5,0)*1000 -> 285953.58 | G8: =ccs!$H$6*ccs!B26*8760 -> 1375695.8 | H8: =OFFSET(gas!$F$18,(ROW(gas!E7)-1)*5,0)*1000 -> 318222.71 | I8: =ccs!$H$6*ccs!B26*8760 -> 1375695.8 | J8: =OFFSET(land!$C$12,(ROW(J7)-1)*5,0)*1000 -> 783952.07 | K8: =OFFSET(offshore!$K$13,(ROW(K7)-1)*5,0)*1000 -> 1946500.3 | L8: =OFFSET(coal!$C$20,(ROW(L7)-1)*5,0)*1000 -> 495210.68 | M8: =ccs!$C$6*ccs!B26*8760 -> 1435580.4 | N8: =OFFSET(coal!$F$20,(ROW(N7)-1)*5,0)*1000 -> 1029882.2 | O8: =ccs!$F$6*ccs!B26*8760 -> 1089584.5 | P8: =OFFSET(nuclear!$B$8,(ROW(P7)-1)*5,0)*1000 -> 1738729.6 | Q8: =5969/6.5*1000 -> 918307.69 | R8: =2240.15384615385*1000 -> 2240153.8 | S8: =SMR!T8 -> 425590.3 | T8: =ccs!$J$6*ccs!B26*8760 -> 357991.33 | U8: =SMR!V8 -> 2603313.4 | V8: =ccs!$J$6*ccs!B26*8760 -> 357991.33 | W8: =OFFSET(Electrolyzer!$C$2,(ROW(W7)-1)*5,0)*1000 -> 311272.5 | X8: ='Fuel cell'!C8*1000 -> 962115 | Y8: =OFFSET('H2 turbine'!$B$12,(ROW(Z7)-1)*5,0)*1000 -> 305111.11 | Z8: ='hydrogen storage'!B15 -> 24901.8 | AA8: ='hydrogen storage'!D15 -> 1448.832 | AB8: =1.93*1.1*1.0928 -> 2.3200144 | AC8: =AB8*2 -> 4.6400288 | AD8: =3.18*1.1*1.0928 -> 3.8226144 | AE8: =DAC!B25*8760 -> 2037420

Sheet advance_hydrogen
A1: Vintage | B1: Battery_Storage | C1: Battery_Storage_energy | D1: Central_PV | E1: Residential_PV | F1: Gas_Combustion_Turbine | G1: Gas_Combustion_Turbine_CCS | H1: Gas_CCGT | I1: Gas_CCGT_CCS | J1: Wind | K1: Offshore_Wind | L1: Coal | M1: Coal_CCS | N1: Coal_IGCC | O1: Coal_IGCC_CCS | P1: Nuclear | Q1: Hydro_Pumped | R1: Hydro_NonPumped | S1: SMR | T1: SMR_CCS | U1: Gasification | V1: Gasification_CCS | W1: Electrolyzer | X1: Fuel_cell | Y1: Hydrogen_turbine | Z1: Tank | AA1: Salt_cavern | AB1: CCS_storage_oil | AC1: CCS_storage_saline | AD1: CCS_storage_offshore | AE1: DAC
A2: 2020 | B2: =OFFSET(battery!$F$15,(ROW(B1)-1)*5,0)*1000 -> 492307.69 | C2: =OFFSET(battery!$C$15,(ROW(C1)-1)*5,0)*1000 -> 246153.85 | D2: =OFFSET(Solar!$C$11,(ROW(D1)-1)*5,0)*1000 -> 628000 | E2: =OFFSET(Solar!$F$11,(ROW(Solar!E1)-1)*5,0)*1000 -> 746000 | F2: =OFFSET(gas!$C$18,(ROW(gas!C1)-1)*5,0)*1000 -> 367230.77 | G2: =ccs!$H$6*ccs!B20*8760 -> 2957746.1 | H2: =OFFSET(gas!$F$18,(ROW(gas!E1)-1)*5,0)*1000 -> 408913.26 | I2: =ccs!$H$6*ccs!B20*8760 -> 2957746.1 | J2: =OFFSET(land!$C$12,(ROW(J1)-1)*5,0)*1000 -> 1157000 | K2: =OFFSET(offshore!$K$13,(ROW(K1)-1)*5,0)*1000 -> 2857000 | L2: =OFFSET(coal!$C$20,(ROW(L1)-1)*5,0)*1000 -> 622461.54 | M2: =ccs!$C$6*ccs!B20*8760 -> 3086497.8 | N2: =OFFSET(coal!$F$20,(ROW(N1)-1)*5,0)*1000 -> 1089999.5 | O2: =ccs!$F$6*ccs!B20*8760 -> 2342606.6 | P2: =OFFSET(nuclear!$B$8,(ROW(P1)-1)*5,0)*1000 -> 2461538.5 | Q2: =5969/6.5*1000 -> 918307.69 | R2: =2240.15384615385*1000 -> 2240153.8 | S2: =SMR!T2 -> 546556.72 | T2: =ccs!$J$6*ccs!B20*8760 -> 769681.35 | U2: =SMR!V2 -> 3272268.8 | V2: =ccs!$J$6*ccs!B20 -> 87.863168 | W2: =OFFSET(Electrolyzer!$C$2,(ROW(W1)-1)*5,0)*1000 -> 1245090 | X2: ='Fuel cell'!C2*1000 -> 1562022 | Y2: =OFFSET('H2 turbine'!$B$12,(ROW(Z1)-1)*5,0)*1000 -> 314777.78 | Z2: ='hydrogen storage'!B9 -> 69045.9 | AA2: ='hydrogen storage'!D9 -> 3610.761 | AB2: =2.36*1.1*1.0928 -> 2.8369088 | AC2: =AB2*2 -> 5.6738176 | AD2: =3.89*1.1*1.0928 -> 4.6760912 | AE2: =DAC!B19*8760 -> 7357350
A3: 2025 | B3: =OFFSET(battery!$F$15,(ROW(B2)-1)*5,0)*1000 -> 474606.98 | C3: =OFFSET(battery!$C$15,(ROW(C2)-1)*5,0)*1000 -> 219340.56 | D3: =OFFSET(Solar!$C$11,(ROW(D2)-1)*5,0)*1000 -> 607009.58 | E3: =OFFSET(Solar!$F$11,(ROW(Solar!E2)-1)*5,0)*1000 -> 686543.83 | F3: =OFFSET(gas!$C$18,(ROW(gas!C2)-1)*5,0)*1000 -> 358513.34 | G3: =ccs!$H$6*ccs!B21*8760 -> 2063543.8 | H3: =OFFSET(gas!$F$18,(ROW(gas!E2)-1)*5,0)*1000 -> 398327.81 | I3: =ccs!$H$6*ccs!B21*8760 -> 2063543.8 | J3: =OFFSET(land!$C$12,(ROW(J2)-1)*5,0)*1000 -> 1076641 | K3: =OFFSET(offshore!$K$13,(ROW(K2)-1)*5,0)*1000 -> 2492044 | L3: =OFFSET(coal!$C$20,(ROW(L2)-1)*5,0)*1000 -> 612285.83 | M3: =ccs!$C$6*ccs!B21*8760 -> 2153370.6 | N3: =OFFSET(coal!$F$20,(ROW(N2)-1)*5,0)*1000 -> 1083549.8 | O3: =ccs!$F$6*ccs!B21*8760 -> 1634376.7 | P3: =OFFSET(nuclear!$B$8,(ROW(P2)-1)*5,0)*1000 -> 2113664.3 | Q3: =5969/6.5*1000 -> 918307.69 | R3: =2240.15384615385*1000 -> 2240153.8 | S3: =SMR!T3 -> 533582.41 | T3: =ccs!$J$6*ccs!B21*8760 -> 536986.99 | U3: =SMR!V3 -> 3218775.3 | V3: =ccs!$J$6*ccs!B21 -> 61.299884 | W3: =OFFSET(Electrolyzer!$C$2,(ROW(W2)-1)*5,0)*1000 -> 905520 | X3: ='Fuel cell'!C3*1000 -> 1443172.5 | Y3: =OFFSET('H2 turbine'!$B$12,(ROW(Z2)-1)*5,0)*1000 -> 313166.67 | Z3: ='hydrogen storage'!B10 -> 61688.55 | AA3: ='hydrogen storage'!D10 -> 3010.854 | AB3: =2.25*1.1*1.0928 -> 2.70468 | AC3: =AB3*2 -> 5.40936 | AD3: =3.7*1.1*1.0928 -> 4.447696 | AE3: =DAC!B20*8760 -> 5433120
A4: 2030 | B4: =OFFSET(battery!$F$15,(ROW(B3)-1)*5,0)*1000 -> 483790.42 | C4: =OFFSET(battery!$C$15,(ROW(C3)-1)*5,0)*1000 -> 173879.95 | D4: =OFFSET(Solar!$C$11,(ROW(D3)-1)*5,0)*1000 -> 505217.02 | E4: =OFFSET(Solar!$F$11,(ROW(Solar!E3)-1)*5,0)*1000 -> 548996.6 | F4: =OFFSET(gas!$C$18,(ROW(gas!C3)-1)*5,0)*1000 -> 344008.72 | G4: =ccs!$H$6*ccs!B22*8760 -> 1719619.8 | H4: =OFFSET(gas!$F$18,(ROW(gas!E3)-1)*5,0)*1000 -> 380673.19 | I4: =ccs!$H$6*ccs!B22*8760 -> 1719619.8 | J4: =OFFSET(land!$C$12,(ROW(J3)-1)*5,0)*1000 -> 976192.22 | K4: =OFFSET(offshore!$K$13,(ROW(K3)-1)*5,0)*1000 -> 2290687.3 | L4: =OFFSET(coal!$C$20,(ROW(L3)-1)*5,0)*1000 -> 595355.36 | M4: =ccs!$C$6*ccs!B22*8760 -> 1794475.5 | N4: =OFFSET(coal!$F$20,(ROW(N3)-1)*5,0)*1000 -> 1072807.6 | O4: =ccs!$F$6*ccs!B22*8760 -> 1361980.6 | P4: =OFFSET(nuclear!$B$8,(ROW(P3)-1)*5,0)*1000 -> 2015508 | Q4: =5969/6.5*1000 -> 918307.69 | R4: =2240.15384615385*1000 -> 2240153.8 | S4: =SMR!T4 -> 511994.89 | T4: =ccs!$J$6*ccs!B22*8760 -> 447489.16 | U4: =SMR!V4 -> 3129772.1 | V4: =ccs!$J$6*ccs!B22 -> 51.083237 | W4: =OFFSET(Electrolyzer!$C$2,(ROW(W3)-1)*5,0)*1000 -> 565950 | X4: ='Fuel cell'!C4*1000 -> 1324323 | Y4: =OFFSET('H2 turbine'!$B$12,(ROW(Z3)-1)*5,0)*1000 -> 311555.56 | Z4: ='hydrogen storage'!B11 -> 54331.2 | AA4: ='hydrogen storage'!D11 -> 2410.947 | AB4: =2.14*1.1*1.0928 -> 2.5724512 | AC4: =AB4*2 -> 5.1449024 | AD4: =3.52*1.1*1.0928 -> 4.2313216 | AE4: =DAC!B21*8760 -> 3395700
A5: 2035 | B5: =OFFSET(battery!$F$15,(ROW(B4)-1)*5,0)*1000 -> 467109.57 | C5: =OFFSET(battery!$C$15,(ROW(C4)-1)*5,0)*1000 -> 158078 | D5: =OFFSET(Solar!$C$11,(ROW(D4)-1)*5,0)*1000 -> 403424.47 | E5: =OFFSET(Solar!$F$11,(ROW(Solar!E4)-1)*5,0)*1000 -> 411449.37 | F5: =OFFSET(gas!$C$18,(ROW(gas!C4)-1)*5,0)*1000 -> 329504.09 | G5: =ccs!$H$6*ccs!B23*8760 -> 1582050.2 | H5: =OFFSET(gas!$F$18,(ROW(gas!E4)-1)*5,0)*1000 -> 363018.57 | I5: =ccs!$H$6*ccs!B23*8760 -> 1582050.2 | J5: =OFFSET(land!$C$12,(ROW(J4)-1)*5,0)*1000 -> 928132.19 | K5: =OFFSET(offshore!$K$13,(ROW(K4)-1)*5,0)*1000 -> 2166215.1 | L5: =OFFSET(coal!$C$20,(ROW(L4)-1)*5,0)*1000 -> 578403.11 | M5: =ccs!$C$6*ccs!B23*8760 -> 1650917.4 | N5: =OFFSET(coal!$F$20,(ROW(N4)-1)*5,0)*1000 -> 1062087.1 | O5: =ccs!$F$6*ccs!B23*8760 -> 1253022.1 | P5: =OFFSET(nuclear!$B$8,(ROW(P4)-1)*5,0)*1000 -> 1948571.2 | Q5: =5969/6.5*1000 -> 918307.69 | R5: =2240.15384615385*1000 -> 2240153.8 | S5: =SMR!T5 -> 490407.37 | T5: =ccs!$J$6*ccs!B23*8760 -> 411690.02 | U5: =SMR!V5 -> 3040654.4 | V5: =ccs!$J$6*ccs!B23 -> 46.996578 | W5: =OFFSET(Electrolyzer!$C$2,(ROW(W4)-1)*5,0)*1000 -> 694166.67 | X5: ='Fuel cell'!C5*1000 -> 1233771 | Y5: =OFFSET('H2 turbine'!$B$12,(ROW(Z4)-1)*5,0)*1000 -> 309944.44 | Z5: ='hydrogen storage'!B12 -> 43578.15 | AA5: ='hydrogen storage'!D12 -> 2110.9935 | AB5: =(AB4+AB6)/2 -> 2.4462328 | AC5: =AB5*2 -> 4.8924656 | AD5: =(AD4+AD6)/2 -> 4.026968 | AE5: =DAC!B22*8760 -> 2886345
A6: 2040 | B6: =OFFSET(battery!$F$15,(ROW(B5)-1)*5,0)*1000 -> 449709.83 | C6: =OFFSET(battery!$C$15,(ROW(C5)-1)*5,0)*1000 -> 142362.74 | D6: =OFFSET(Solar!$C$11,(ROW(D5)-1)*5,0)*1000 -> 371518.84 | E6: =OFFSET(Solar!$F$11,(ROW(Solar!E5)-1)*5,0)*1000 -> 371597.4 | F6: =OFFSET(gas!$C$18,(ROW(gas!C5)-1)*5,0)*1000 -> 314962.84 | G6: =ccs!$H$6*ccs!B24*8760 -> 1444480.6 | H6: =OFFSET(gas!$F$18,(ROW(gas!E5)-1)*5,0)*1000 -> 348074.41 | I6: =ccs!$H$6*ccs!B24*8760 -> 1444480.6 | J6: =OFFSET(land!$C$12,(ROW(J5)-1)*5,0)*1000 -> 880072.15 | K6: =OFFSET(offshore!$K$13,(ROW(K5)-1)*5,0)*1000 -> 2075879.5 | L6: =OFFSET(coal!$C$20,(ROW(L5)-1)*5,0)*1000 -> 550665.03 | M6: =ccs!$C$6*ccs!B24*8760 -> 1507359.4 | N6: =OFFSET(coal!$F$20,(ROW(N5)-1)*5,0)*1000 -> 1051344.9 | O6: =ccs!$F$6*ccs!B24*8760 -> 1144063.7 | P6: =OFFSET(nuclear!$B$8,(ROW(P5)-1)*5,0)*1000 -> 1879782.7 | Q6: =5969/6.5*1000 -> 918307.69 | R6: =2240.15384615385*1000 -> 2240153.8 | S6: =SMR!T6 -> 468765.34 | T6: =ccs!$J$6*ccs!B24*8760 -> 375890.89 | U6: =SMR!V6 -> 2894835.9 | V6: =ccs!$J$6*ccs!B24 -> 42.909919 | W6: =OFFSET(Electrolyzer!$C$2,(ROW(W5)-1)*5,0)*1000 -> 452760 | X6: ='Fuel cell'!C6*1000 -> 1143219 | Y6: =OFFSET('H2 turbine'!$B$12,(ROW(Z5)-1)*5,0)*1000 -> 308333.33 | Z6: ='hydrogen storage'!B13 -> 32825.1 | AA6: ='hydrogen storage'!D13 -> 1811.04 | AB6: =1.93*1.1*1.0928 -> 2.3200144 | AC6: =AB6*2 -> 4.6400288 | AD6: =3.18*1.1*1.0928 -> 3.8226144 | AE6: =DAC!B23*8760 -> 2376990
A7: 2045 | B7: =OFFSET(battery!$F$15,(ROW(B6)-1)*5,0)*1000 -> 431425.3 | C7: =OFFSET(battery!$C$15,(ROW(C6)-1)*5,0)*1000 -> 126754.17 | D7: =OFFSET(Solar!$C$11,(ROW(D6)-1)*5,0)*1000 -> 339613.21 | E7: =OFFSET(Solar!$F$11,(ROW(Solar!E6)-1)*5,0)*1000 -> 331745.43 | F7: =OFFSET(gas!$C$18,(ROW(gas!C6)-1)*5,0)*1000 -> 300458.21 | G7: =ccs!$H$6*ccs!B25*8760 -> 1410088.2 | H7: =OFFSET(gas!$F$18,(ROW(gas!E6)-1)*5,0)*1000 -> 333130.25 | I7: =ccs!$H$6*ccs!B25*8760 -> 1410088.2 | J7: =OFFSET(land!$C$12,(ROW(J6)-1)*5,0)*1000 -> 832012.11 | K7: =OFFSET(offshore!$K$13,(ROW(K6)-1)*5,0)*1000 -> 2004930.7 | L7: =OFFSET(coal!$C$20,(ROW(L6)-1)*5,0)*1000 -> 522948.75 | M7: =ccs!$C$6*ccs!B25*8760 -> 1471469.9 | N7: =OFFSET(coal!$F$20,(ROW(N6)-1)*5,0)*1000 -> 1040624.4 | O7: =ccs!$F$6*ccs!B25*8760 -> 1116824.1 | P7: =OFFSET(nuclear!$B$8,(ROW(P6)-1)*5,0)*1000 -> 1815208.1 | Q7: =5969/6.5*1000 -> 918307.69 | R7: =2240.15384615385*1000 -> 2240153.8 | S7: =SMR!T7 -> 447177.82 | T7: =ccs!$J$6*ccs!B25*8760 -> 366941.11 | U7: =SMR!V7 -> 2749131.9 | V7: =ccs!$J$6*ccs!B25 -> 41.888254 | W7: =OFFSET(Electrolyzer!$C$2,(ROW(W6)-1)*5,0)*1000 -> 639833.33 | X7: ='Fuel cell'!C7*1000 -> 1052667 | Y7: =OFFSET('H2 turbine'!$B$12,(ROW(Z6)-1)*5,0)*1000 -> 306722.22 | Z7: ='hydrogen storage'!B14 -> 28863.45 | AA7: ='hydrogen storage'!D14 -> 1629.936 | AB7: =1.93*1.1*1.0928 -> 2.3200144 | AC7: =AB7*2 -> 4.6400288 | AD7: =3.18*1.1*1.0928 -> 3.8226144 | AE7: =DAC!B24*8760 -> 2207205
A8: 2050 | B8: =OFFSET(battery!$F$15,(ROW(B7)-1)*5,0)*1000 -> 412034.81 | C8: =OFFSET(battery!$C$15,(ROW(C7)-1)*5,0)*1000 -> 111278.96 | D8: =OFFSET(Solar!$C$11,(ROW(D7)-1)*5,0)*1000 -> 307707.58 | E8: =OFFSET(Solar!$F$11,(ROW(Solar!E7)-1)*5,0)*1000 -> 291893.46 | F8: =OFFSET(gas!$C$18,(ROW(gas!C7)-1)*5,0)*1000 -> 285953.58 | G8: =ccs!$H$6*ccs!B26*8760 -> 1375695.8 | H8: =OFFSET(gas!$F$18,(ROW(gas!E7)-1)*5,0)*1000 -> 318222.71 | I8: =ccs!$H$6*ccs!B26*8760 -> 1375695.8 | J8: =OFFSET(land!$C$12,(ROW(J7)-1)*5,0)*1000 -> 783952.07 | K8: =OFFSET(offshore!$K$13,(ROW(K7)-1)*5,0)*1000 -> 1946500.3 | L8: =OFFSET(coal!$C$20,(ROW(L7)-1)*5,0)*1000 -> 495210.68 | M8: =ccs!$C$6*ccs!B26*8760 -> 1435580.4 | N8: =OFFSET(coal!$F$20,(ROW(N7)-1)*5,0)*1000 -> 1029882.2 | O8: =ccs!$F$6*ccs!B26*8760 -> 1089584.5 | P8: =OFFSET(nuclear!$B$8,(ROW(P7)-1)*5,0)*1000 -> 1738729.6 | Q8: =5969/6.5*1000 -> 918307.69 | R8: =2240.15384615385*1000 -> 2240153.8 | S8: =SMR!T8 -> 425590.3 | T8: =ccs!$J$6*ccs!B26*8760 -> 357991.33 | U8: =SMR!V8 -> 2603313.4 | V8: =ccs!$J$6*ccs!B26 -> 40.86659 | W8: =OFFSET(Electrolyzer!$B$2,(ROW(W7)-1)*5,0)*1000 -> 282975 | X8: ='Fuel cell'!B8*1000 -> 599907 | Y8: =OFFSET('H2 turbine'!$B$12,(ROW(Z7)-1)*5,0)*1000 -> 305111.11 | Z8: ='hydrogen storage'!B16 -> 24901.8 | AA8: ='hydrogen storage'!E15 -> 1199.814 | AB8: =1.93*1.1*1.0928 -> 2.3200144 | AC8: =AB8*2 -> 4.6400288 | AD8: =3.18*1.1*1.0928 -> 3.8226144 | AE8: =DAC!B25*8760 -> 2037420

Sheet conservative_hydrogen
A1: Vintage | B1: Battery_Storage | C1: Battery_Storage_energy | D1: Central_PV | E1: Residential_PV | F1: Gas_Combustion_Turbine | G1: Gas_Combustion_Turbine_CCS | H1: Gas_CCGT | I1: Gas_CCGT_CCS | J1: Wind | K1: Offshore_Wind | L1: Coal | M1: Coal_CCS | N1: Coal_IGCC | O1: Coal_IGCC_CCS | P1: Nuclear | Q1: Hydro_Pumped | R1: Hydro_NonPumped | S1: SMR | T1: SMR_CCS | U1: Gasification | V1: Gasification_CCS | W1: Electrolyzer | X1: Fuel_cell | Y1: Hydrogen_turbine | Z1: Tank | AA1: Salt_cavern | AB1: CCS_storage_oil | AC1: CCS_storage_saline | AD1: CCS_storage_offshore | AE1: DAC
A2: 2020 | B2: =OFFSET(battery!$F$15,(ROW(B1)-1)*5,0)*1000 -> 492307.69 | C2: =OFFSET(battery!$C$15,(ROW(C1)-1)*5,0)*1000 -> 246153.85 | D2: =OFFSET(Solar!$C$11,(ROW(D1)-1)*5,0)*1000 -> 628000 | E2: =OFFSET(Solar!$F$11,(ROW(Solar!E1)-1)*5,0)*1000 -> 746000 | F2: =OFFSET(gas!$C$18,(ROW(gas!C1)-1)*5,0)*1000 -> 367230.77 | G2: =ccs!$H$6*ccs!B20*8760 -> 2957746.1 | H2: =OFFSET(gas!$F$18,(ROW(gas!E1)-1)*5,0)*1000 -> 408913.26 | I2: =ccs!$H$6*ccs!B20*8760 -> 2957746.1 | J2: =OFFSET(land!$C$12,(ROW(J1)-1)*5,0)*1000 -> 1157000 | K2: =OFFSET(offshore!$K$13,(ROW(K1)-1)*5,0)*1000 -> 2857000 | L2: =OFFSET(coal!$C$20,(ROW(L1)-1)*5,0)*1000 -> 622461.54 | M2: =ccs!$C$6*ccs!B20*8760 -> 3086497.8 | N2: =OFFSET(coal!$F$20,(ROW(N1)-1)*5,0)*1000 -> 1089999.5 | O2: =ccs!$F$6*ccs!B20*8760 -> 2342606.6 | P2: =OFFSET(nuclear!$C$8,(ROW(P1)-1)*5,0)*1000 -> 2461538.5 | Q2: =5969/6.5*1000 -> 918307.69 | R2: =2240.15384615385*1000 -> 2240153.8 | S2: =SMR!T2 -> 546556.72 | T2: =ccs!$J$6*ccs!B20*8760 -> 769681.35 | U2: =SMR!V2 -> 3272268.8 | V2: =ccs!$J$6*ccs!B20 -> 87.863168 | W2: =OFFSET(Electrolyzer!$C$2,(ROW(W1)-1)*5,0)*1000 -> 1245090 | X2: ='Fuel cell'!C2*1000 -> 1562022 | Y2: =OFFSET('H2 turbine'!$B$12,(ROW(Z1)-1)*5,0)*1000 -> 314777.78 | Z2: ='hydrogen storage'!B9 -> 69045.9 | AA2: ='hydrogen storage'!D9 -> 3610.761 | AB2: =2.36*1.1*1.0928 -> 2.8369088 | AC2: =AB2*2 -> 5.6738176 | AD2: =3.89*1.1*1.0928 -> 4.6760912 | AE2: =DAC!B19*8760 -> 7357350
A3: 2025 | B3: =OFFSET(battery!$F$15,(ROW(B2)-1)*5,0)*1000 -> 474606.98 | C3: =OFFSET(battery!$C$15,(ROW(C2)-1)*5,0)*1000 -> 219340.56 | D3: =OFFSET(Solar!$C$11,(ROW(D2)-1)*5,0)*1000 -> 607009.58 | E3: =OFFSET(Solar!$F$11,(ROW(Solar!E2)-1)*5,0)*1000 -> 686543.83 | F3: =OFFSET(gas!$C$18,(ROW(gas!C2)-1)*5,0)*1000 -> 358513.34 | G3: =ccs!$H$6*ccs!B21*8760 -> 2063543.8 | H3: =OFFSET(gas!$F$18,(ROW(gas!E2)-1)*5,0)*1000 -> 398327.81 | I3: =ccs!$H$6*ccs!B21*8760 -> 2063543.8 | J3: =OFFSET(land!$C$12,(ROW(J2)-1)*5,0)*1000 -> 1076641 | K3: =OFFSET(offshore!$K$13,(ROW(K2)-1)*5,0)*1000 -> 2492044 | L3: =OFFSET(coal!$C$20,(ROW(L2)-1)*5,0)*1000 -> 612285.83 | M3: =ccs!$C$6*ccs!B21*8760 -> 2153370.6 | N3: =OFFSET(coal!$F$20,(ROW(N2)-1)*5,0)*1000 -> 1083549.8 | O3: =ccs!$F$6*ccs!B21*8760 -> 1634376.7 | P3: =OFFSET(nuclear!$C$8,(ROW(P2)-1)*5,0)*1000 -> 2297494.5 | Q3: =5969/6.5*1000 -> 918307.69 | R3: =2240.15384615385*1000 -> 2240153.8 | S3: =SMR!T3 -> 533582.41 | T3: =ccs!$J$6*ccs!B21*8760 -> 536986.99 | U3: =SMR!V3 -> 3218775.3 | V3: =ccs!$J$6*ccs!B21 -> 61.299884 | W3: =OFFSET(Electrolyzer!$C$2,(ROW(W2)-1)*5,0)*1000 -> 905520 | X3: ='Fuel cell'!C3*1000 -> 1443172.5 | Y3: =OFFSET('H2 turbine'!$B$12,(ROW(Z2)-1)*5,0)*1000 -> 313166.67 | Z3: ='hydrogen storage'!B10 -> 61688.55 | AA3: ='hydrogen storage'!D10 -> 3010.854 | AB3: =2.25*1.1*1.0928 -> 2.70468 | AC3: =AB3*2 -> 5.40936 | AD3: =3.7*1.1*1.0928 -> 4.447696 | AE3: =DAC!B20*8760 -> 5433120
A4: 2030 | B4: =OFFSET(battery!$F$15,(ROW(B3)-1)*5,0)*1000 -> 483790.42 | C4: =OFFSET(battery!$C$15,(ROW(C3)-1)*5,0)*1000 -> 173879.95 | D4: =OFFSET(Solar!$C$11,(ROW(D3)-1)*5,0)*1000 -> 505217.02 | E4: =OFFSET(Solar!$F$11,(ROW(Solar!E3)-1)*5,0)*1000 -> 548996.6 | F4: =OFFSET(gas!$C$18,(ROW(gas!C3)-1)*5,0)*1000 -> 344008.72 | G4: =ccs!$H$6*ccs!B22*8760 -> 1719619.8 | H4: =OFFSET(gas!$F$18,(ROW(gas!E3)-1)*5,0)*1000 -> 380673.19 | I4: =ccs!$H$6*ccs!B22*8760 -> 1719619.8 | J4: =OFFSET(land!$C$12,(ROW(J3)-1)*5,0)*1000 -> 976192.22 | K4: =OFFSET(offshore!$K$13,(ROW(K3)-1)*5,0)*1000 -> 2290687.3 | L4: =OFFSET(coal!$C$20,(ROW(L3)-1)*5,0)*1000 -> 595355.36 | M4: =ccs!$C$6*ccs!B22*8760 -> 1794475.5 | N4: =OFFSET(coal!$F$20,(ROW(N3)-1)*5,0)*1000 -> 1072807.6 | O4: =ccs!$F$6*ccs!B22*8760 -> 1361980.6 | P4: =OFFSET(nuclear!$C$8,(ROW(P3)-1)*5,0)*1000 -> 2297494.5 | Q4: =5969/6.5*1000 -> 918307.69 | R4: =2240.15384615385*1000 -> 2240153.8 | S4: =SMR!T4 -> 511994.89 | T4: =ccs!$J$6*ccs!B22*8760 -> 447489.16 | U4: =SMR!V4 -> 3129772.1 | V4: =ccs!$J$6*ccs!B22 -> 51.083237 | W4: =OFFSET(Electrolyzer!$C$2,(ROW(W3)-1)*5,0)*1000 -> 565950 | X4: ='Fuel cell'!C4*1000 -> 1324323 | Y4: =OFFSET('H2 turbine'!$B$12,(ROW(Z3)-1)*5,0)*1000 -> 311555.56 | Z4: ='hydrogen storage'!B11 -> 54331.2 | AA4: ='hydrogen storage'!D11 -> 2410.947 | AB4: =2.14*1.1*1.0928 -> 2.5724512 | AC4: =AB4*2 -> 5.1449024 | AD4: =3.52*1.1*1.0928 -> 4.2313216 | AE4: =DAC!B21*8760 -> 3395700
A5: 2035 | B5: =OFFSET(battery!$F$15,(ROW(B4)-1)*5,0)*1000 -> 467109.57 | C5: =OFFSET(battery!$C$15,(ROW(C4)-1)*5,0)*1000 -> 158078 | D5: =OFFSET(Solar!$C$11,(ROW(D4)-1)*5,0)*1000 -> 403424.47 | E5: =OFFSET(Solar!$F$11,(ROW(Solar!E4)-1)*5,0)*1000 -> 411449.37 | F5: =OFFSET(gas!$C$18,(ROW(gas!C4)-1)*5,0)*1000 -> 329504.09 | G5: =ccs!$H$6*ccs!B23*8760 -> 1582050.2 | H5: =OFFSET(gas!$F$18,(ROW(gas!E4)-1)*5,0)*1000 -> 363018.57 | I5: =ccs!$H$6*ccs!B23*8760 -> 1582050.2 | J5: =OFFSET(land!$C$12,(ROW(J4)-1)*5,0)*1000 -> 928132.19 | K5: =OFFSET(offshore!$K$13,(ROW(K4)-1)*5,0)*1000 -> 2166215.1 | L5: =OFFSET(coal!$C$20,(ROW(L4)-1)*5,0)*1000 -> 578403.11 | M5: =ccs!$C$6*ccs!B23*8760 -> 1650917.4 | N5: =OFFSET(coal!$F$20,(ROW(N4)-1)*5,0)*1000 -> 1062087.1 | O5: =ccs!$F$6*ccs!B23*8760 -> 1253022.1 | P5: =OFFSET(nuclear!$C$8,(ROW(P4)-1)*5,0)*1000 -> 2297494.5 | Q5: =5969/6.5*1000 -> 918307.69 | R5: =2240.15384615385*1000 -> 2240153.8 | S5: =SMR!T5 -> 490407.37 | T5: =ccs!$J$6*ccs!B23*8760 -> 411690.02 | U5: =SMR!V5 -> 3040654.4 | V5: =ccs!$J$6*ccs!B23 -> 46.996578 | W5: =OFFSET(Electrolyzer!$C$2,(ROW(W4)-1)*5,0)*1000 -> 694166.67 | X5: ='Fuel cell'!C5*1000 -> 1233771 | Y5: =OFFSET('H2 turbine'!$B$12,(ROW(Z4)-1)*5,0)*1000 -> 309944.44 | Z5: ='hydrogen storage'!B12 -> 43578.15 | AA5: ='hydrogen storage'!D12 -> 2110.9935 | AB5: =(AB4+AB6)/2 -> 2.4462328 | AC5: =AB5*2 -> 4.8924656 | AD5: =(AD4+AD6)/2 -> 4.026968 | AE5: =DAC!B22*8760 -> 2886345
A6: 2040 | B6: =OFFSET(battery!$F$15,(ROW(B5)-1)*5,0)*1000 -> 449709.83 | C6: =OFFSET(battery!$C$15,(ROW(C5)-1)*5,0)*1000 -> 142362.74 | D6: =OFFSET(Solar!$C$11,(ROW(D5)-1)*5,0)*1000 -> 371518.84 | E6: =OFFSET(Solar!$F$11,(ROW(Solar!E5)-1)*5,0)*1000 -> 371597.4 | F6: =OFFSET(gas!$C$18,(ROW(gas!C5)-1)*5,0)*1000 -> 314962.84 | G6: =ccs!$H$6*ccs!B24*8760 -> 1444480.6 | H6: =OFFSET(gas!$F$18,(ROW(gas!E5)-1)*5,0)*1000 -> 348074.41 | I6: =ccs!$H$6*ccs!B24*8760 -> 1444480.6 | J6: =OFFSET(land!$C$12,(ROW(J5)-1)*5,0)*1000 -> 880072.15 | K6: =OFFSET(offshore!$K$13,(ROW(K5)-1)*5,0)*1000 -> 2075879.5 | L6: =OFFSET(coal!$C$20,(ROW(L5)-1)*5,0)*1000 -> 550665.03 | M6: =ccs!$C$6*ccs!B24*8760 -> 1507359.4 | N6: =OFFSET(coal!$F$20,(ROW(N5)-1)*5,0)*1000 -> 1051344.9 | O6: =ccs!$F$6*ccs!B24*8760 -> 1144063.7 | P6: =OFFSET(nuclear!$C$8,(ROW(P5)-1)*5,0)*1000 -> 2297494.5 | Q6: =5969/6.5*1000 -> 918307.69 | R6: =2240.15384615385*1000 -> 2240153.8 | S6: =SMR!T6 -> 468765.34 | T6: =ccs!$J$6*ccs!B24*8760 -> 375890.89 | U6: =SMR!V6 -> 2894835.9 | V6: =ccs!$J$6*ccs!B24 -> 42.909919 | W6: =OFFSET(Electrolyzer!$C$2,(ROW(W5)-1)*5,0)*1000 -> 452760 | X6: ='Fuel cell'!C6*1000 -> 1143219 | Y6: =OFFSET('H2 turbine'!$B$12,(ROW(Z5)-1)*5,0)*1000 -> 308333.33 | Z6: ='hydrogen storage'!B13 -> 32825.1 | AA6: ='hydrogen storage'!D13 -> 1811.04 | AB6: =1.93*1.1*1.0928 -> 2.3200144 | AC6: =AB6*2 -> 4.6400288 | AD6: =3.18*1.1*1.0928 -> 3.8226144 | AE6: =DAC!B23*8760 -> 2376990
A7: 2045 | B7: =OFFSET(battery!$F$15,(ROW(B6)-1)*5,0)*1000 -> 431425.3 | C7: =OFFSET(battery!$C$15,(ROW(C6)-1)*5,0)*1000 -> 126754.17 | D7: =OFFSET(Solar!$C$11,(ROW(D6)-1)*5,0)*1000 -> 339613.21 | E7: =OFFSET(Solar!$F$11,(ROW(Solar!E6)-1)*5,0)*1000 -> 331745.43 | F7: =OFFSET(gas!$C$18,(ROW(gas!C6)-1)*5,0)*1000 -> 300458.21 | G7: =ccs!$H$6*ccs!B25*8760 -> 1410088.2 | H7: =OFFSET(gas!$F$18,(ROW(gas!E6)-1)*5,0)*1000 -> 333130.25 | I7: =ccs!$H$6*ccs!B25*8760 -> 1410088.2 | J7: =OFFSET(land!$C$12,(ROW(J6)-1)*5,0)*1000 -> 832012.11 | K7: =OFFSET(offshore!$K$13,(ROW(K6)-1)*5,0)*1000 -> 2004930.7 | L7: =OFFSET(coal!$C$20,(ROW(L6)-1)*5,0)*1000 -> 522948.75 | M7: =ccs!$C$6*ccs!B25*8760 -> 1471469.9 | N7: =OFFSET(coal!$F$20,(ROW(N6)-1)*5,0)*1000 -> 1040624.4 | O7: =ccs!$F$6*ccs!B25*8760 -> 1116824.1 | P7: =OFFSET(nuclear!$C$8,(ROW(P6)-1)*5,0)*1000 -> 2297494.5 | Q7: =5969/6.5*1000 -> 918307.69 | R7: =2240.15384615385*1000 -> 2240153.8 | S7: =SMR!T7 -> 447177.82 | T7: =ccs!$J$6*ccs!B25*8760 -> 366941.11 | U7: =SMR!V7 -> 2749131.9 | V7: =ccs!$J$6*ccs!B25 -> 41.888254 | W7: =OFFSET(Electrolyzer!$C$2,(ROW(W6)-1)*5,0)*1000 -> 639833.33 | X7: ='Fuel cell'!C7*1000 -> 1052667 | Y7: =OFFSET('H2 turbine'!$B$12,(ROW(Z6)-1)*5,0)*1000 -> 306722.22 | Z7: ='hydrogen storage'!B14 -> 28863.45 | AA7: ='hydrogen storage'!D14 -> 1629.936 | AB7: =1.93*1.1*1.0928 -> 2.3200144 | AC7: =AB7*2 -> 4.6400288 | AD7: =3.18*1.1*1.0928 -> 3.8226144 | AE7: =DAC!B24*8760 -> 2207205
A8: 2050 | B8: =OFFSET(battery!$F$15,(ROW(B7)-1)*5,0)*1000 -> 412034.81 | C8: =OFFSET(battery!$C$15,(ROW(C7)-1)*5,0)*1000 -> 111278.96 | D8: =OFFSET(Solar!$C$11,(ROW(D7)-1)*5,0)*1000 -> 307707.58 | E8: =OFFSET(Solar!$F$11,(ROW(Solar!E7)-1)*5,0)*1000 -> 291893.46 | F8: =OFFSET(gas!$C$18,(ROW(gas!C7)-1)*5,0)*1000 -> 285953.58 | G8: =ccs!$H$6*ccs!B26*8760 -> 1375695.8 | H8: =OFFSET(gas!$F$18,(ROW(gas!E7)-1)*5,0)*1000 -> 318222.71 | I8: =ccs!$H$6*ccs!B26*8760 -> 1375695.8 | J8: =OFFSET(land!$C$12,(ROW(J7)-1)*5,0)*1000 -> 783952.07 | K8: =OFFSET(offshore!$K$13,(ROW(K7)-1)*5,0)*1000 -> 1946500.3 | L8: =OFFSET(coal!$C$20,(ROW(L7)-1)*5,0)*1000 -> 495210.68 | M8: =ccs!$C$6*ccs!B26*8760 -> 1435580.4 | N8: =OFFSET(coal!$F$20,(ROW(N7)-1)*5,0)*1000 -> 1029882.2 | O8: =ccs!$F$6*ccs!B26*8760 -> 1089584.5 | P8: =OFFSET(nuclear!$C$8,(ROW(P7)-1)*5,0)*1000 -> 2297494.5 | Q8: =5969/6.5*1000 -> 918307.69 | R8: =2240.15384615385*1000 -> 2240153.8 | S8: =SMR!T8 -> 425590.3 | T8: =ccs!$J$6*ccs!B26*8760 -> 357991.33 | U8: =SMR!V8 -> 2603313.4 | V8: =ccs!$J$6*ccs!B26 -> 40.86659 | W8: =OFFSET(Electrolyzer!$D$2,(ROW(W7)-1)*5,0)*1000 -> 385000 | X8: ='Fuel cell'!D8*1000 -> 1086624 | Y8: =OFFSET('H2 turbine'!$B$12,(ROW(Z7)-1)*5,0)*1000 -> 305111.11 | Z8: ='hydrogen storage'!B17 -> 41880.3 | AA8: ='hydrogen storage'!F15 -> 2161.929 | AB8: =1.93*1.1*1.0928 -> 2.3200144 | AC8: =AB8*2 -> 4.6400288 | AD8: =3.18*1.1*1.0928 -> 3.8226144 | AE8: =DAC!B25*8760 -> 2037420

Sheet High_cost_PV
A1: Vintage | B1: Battery_Storage | C1: Battery_Storage_energy | D1: Central_PV | E1: Residential_PV | F1: Gas_Combustion_Turbine | G1: Gas_Combustion_Turbine_CCS | H1: Gas_CCGT | I1: Gas_CCGT_CCS | J1: Wind | K1: Offshore_Wind | L1: Coal | M1: Coal_CCS | N1: Coal_IGCC | O1: Coal_IGCC_CCS | P1: Nuclear | Q1: Hydro_Pumped | R1: Hydro_NonPumped | S1: SMR | T1: SMR_CCS | U1: Gasification | V1: Gasification_CCS | W1: Electrolyzer | X1: Fuel_cell | Y1: Hydrogen_turbine | Z1: Tank | AA1: Salt_cavern | AB1: CCS_storage_oil | AC1: CCS_storage_saline | AD1: CCS_storage_offshore | AE1: DAC
A2: 2020 | B2: =OFFSET(battery!$F$15,(ROW(B1)-1)*5,0)*1000 -> 492307.69 | C2: =OFFSET(battery!$C$15,(ROW(C1)-1)*5,0)*1000 -> 246153.85 | D2: =OFFSET(Solar!$C$11,(ROW(D1)-1)*5,0)*1000 -> 628000 | E2: =OFFSET(Solar!$F$11,(ROW(Solar!E1)-1)*5,0)*1000 -> 746000 | F2: =OFFSET(gas!$C$18,(ROW(gas!C1)-1)*5,0)*1000 -> 367230.77 | G2: =ccs!$H$6*ccs!B20 -> 337.64225 | H2: =OFFSET(gas!$F$18,(ROW(gas!E1)-1)*5,0)*1000 -> 408913.26 | I2: =ccs!$H$6*ccs!B20 -> 337.64225 | J2: =OFFSET(land!$C$12,(ROW(J1)-1)*5,0)*1000 -> 1157000 | K2: =OFFSET(offshore!$K$13,(ROW(K1)-1)*5,0)*1000 -> 2857000 | L2: =OFFSET(coal!$C$20,(ROW(L1)-1)*5,0)*1000 -> 622461.54 | M2: =ccs!$C$6*ccs!B20 -> 352.33994 | N2: =OFFSET(coal!$F$20,(ROW(N1)-1)*5,0)*1000 -> 1089999.5 | O2: =ccs!$F$6*ccs!B20 -> 267.42084 | P2: =OFFSET(nuclear!$B$8,(ROW(P1)-1)*5,0)*1000 -> 2461538.5 | Q2: =5969/6.5*1000 -> 918307.69 | R2: =2240.15384615385*1000 -> 2240153.8 | S2: =SMR!T2 -> 546556.72 | T2: =ccs!$J$6*ccs!B20 -> 87.863168 | U2: =SMR!V2 -> 3272268.8 | V2: =ccs!$J$6*ccs!B20 -> 87.863168 | W2: =OFFSET(Electrolyzer!$C$2,(ROW(W1)-1)*5,0)*1000 -> 1245090 | X2: ='Fuel cell'!C2*1000 -> 1562022 | Y2: =OFFSET('H2 turbine'!$B$12,(ROW(Z1)-1)*5,0)*1000 -> 314777.78 | Z2: ='hydrogen storage'!B9 -> 69045.9 | AA2: ='hydrogen storage'!D9 -> 3610.761 | AB2: =2.36*1.1*1.0928 -> 2.8369088 | AC2: =AB2*2 -> 5.6738176 | AD2: =3.89*1.1*1.0928 -> 4.6760912 | AE2: =DAC!B19 -> 839.88014
A3: 2025 | B3: =OFFSET(battery!$F$15,(ROW(B2)-1)*5,0)*1000 -> 474606.98 | C3: =OFFSET(battery!$C$15,(ROW(C2)-1)*5,0)*1000 -> 219340.56 | D3: 628000 | E3: 746000 | F3: =OFFSET(gas!$C$18,(ROW(gas!C2)-1)*5,0)*1000 -> 358513.34 | G3: =ccs!$H$6*ccs!B21 -> 235.56436 | H3: =OFFSET(gas!$F$18,(ROW(gas!E2)-1)*5,0)*1000 -> 398327.81 | I3: =ccs!$H$6*ccs!B21 -> 235.56436 | J3: =OFFSET(land!$C$12,(ROW(J2)-1)*5,0)*1000 -> 1076641 | K3: =OFFSET(offshore!$K$13,(ROW(K2)-1)*5,0)*1000 -> 2492044 | L3: =OFFSET(coal!$C$20,(ROW(L2)-1)*5,0)*1000 -> 612285.83 | M3: =ccs!$C$6*ccs!B21 -> 245.81856 | N3: =OFFSET(coal!$F$20,(ROW(N2)-1)*5,0)*1000 -> 1083549.8 | O3: =ccs!$F$6*ccs!B21 -> 186.57268 | P3: =OFFSET(nuclear!$B$8,(ROW(P2)-1)*5,0)*1000 -> 2113664.3 | Q3: =5969/6.5*1000 -> 918307.69 | R3: =2240.15384615385*1000 -> 2240153.8 | S3: =SMR!T3 -> 533582.41 | T3: =ccs!$J$6*ccs!B21 -> 61.299884 | U3: =SMR!V3 -> 3218775.3 | V3: =ccs!$J$6*ccs!B21 -> 61.299884 | W3: 1245090 | X3: 1562022 | Y3: =OFFSET('H2 turbine'!$B$12,(ROW(Z2)-1)*5,0)*1000 -> 313166.67 | Z3: 69045.9 | AA3: ='hydrogen storage'!D10 -> 3010.854 | AB3: =2.25*1.1*1.0928 -> 2.70468 | AC3: =AB3*2 -> 5.40936 | AD3: =3.7*1.1*1.0928 -> 4.447696 | AE3: =DAC!B20 -> 620.21918
A4: 2030 | B4: =OFFSET(battery!$F$15,(ROW(B3)-1)*5,0)*1000 -> 483790.42 | C4: =OFFSET(battery!$C$15,(ROW(C3)-1)*5,0)*1000 -> 173879.95 | D4: 628000 | E4: 746000 | F4: =OFFSET(gas!$C$18,(ROW(gas!C3)-1)*5,0)*1000 -> 344008.72 | G4: =ccs!$H$6*ccs!B22 -> 196.30363 | H4: =OFFSET(gas!$F$18,(ROW(gas!E3)-1)*5,0)*1000 -> 380673.19 | I4: =ccs!$H$6*ccs!B22 -> 196.30363 | J4: =OFFSET(land!$C$12,(ROW(J3)-1)*5,0)*1000 -> 976192.22 | K4: =OFFSET(offshore!$K$13,(ROW(K3)-1)*5,0)*1000 -> 2290687.3 | L4: =OFFSET(coal!$C$20,(ROW(L3)-1)*5,0)*1000 -> 595355.36 | M4: =ccs!$C$6*ccs!B22 -> 204.8488 | N4: =OFFSET(coal!$F$20,(ROW(N3)-1)*5,0)*1000 -> 1072807.6 | O4: =ccs!$F$6*ccs!B22 -> 155.47723 | P4: =OFFSET(nuclear!$B$8,(ROW(P3)-1)*5,0)*1000 -> 2015508 | Q4: =5969/6.5*1000 -> 918307.69 | R4: =2240.15384615385*1000 -> 2240153.8 | S4: =SMR!T4 -> 511994.89 | T4: =ccs!$J$6*ccs!B22 -> 51.083237 | U4: =SMR!V4 -> 3129772.1 | V4: =ccs!$J$6*ccs!B22 -> 51.083237 | W4: 1245090 | X4: 1562022 | Y4: =OFFSET('H2 turbine'!$B$12,(ROW(Z3)-1)*5,0)*1000 -> 311555.56 | Z4: 69045.9 | AA4: ='hydrogen storage'!D11 -> 2410.947 | AB4: =2.14*1.1*1.0928 -> 2.5724512 | AC4: =AB4*2 -> 5.1449024 | AD4: =3.52*1.1*1.0928 -> 4.2313216 | AE4: =DAC!B21 -> 387.63699
A5: 2035 | B5: =OFFSET(battery!$F$15,(ROW(B4)-1)*5,0)*1000 -> 467109.57 | C5: =OFFSET(battery!$C$15,(ROW(C4)-1)*5,0)*1000 -> 158078 | D5: 628000 | E5: 746000 | F5: =OFFSET(gas!$C$18,(ROW(gas!C4)-1)*5,0)*1000 -> 329504.09 | G5: =ccs!$H$6*ccs!B23 -> 180.59934 | H5: =OFFSET(gas!$F$18,(ROW(gas!E4)-1)*5,0)*1000 -> 363018.57 | I5: =ccs!$H$6*ccs!B23 -> 180.59934 | J5: =OFFSET(land!$C$12,(ROW(J4)-1)*5,0)*1000 -> 928132.19 | K5: =OFFSET(offshore!$K$13,(ROW(K4)-1)*5,0)*1000 -> 2166215.1 | L5: =OFFSET(coal!$C$20,(ROW(L4)-1)*5,0)*1000 -> 578403.11 | M5: =ccs!$C$6*ccs!B23 -> 188.4609 | N5: =OFFSET(coal!$F$20,(ROW(N4)-1)*5,0)*1000 -> 1062087.1 | O5: =ccs!$F$6*ccs!B23 -> 143.03906 | P5: =OFFSET(nuclear!$B$8,(ROW(P4)-1)*5,0)*1000 -> 1948571.2 | Q5: =5969/6.5*1000 -> 918307.69 | R5: =2240.15384615385*1000 -> 2240153.8 | S5: =SMR!T5 -> 490407.37 | T5: =ccs!$J$6*ccs!B23 -> 46.996578 | U5: =SMR!V5 -> 3040654.4 | V5: =ccs!$J$6*ccs!B23 -> 46.996578 | W5: 1245090 | X5: 1562022 | Y5: =OFFSET('H2 turbine'!$B$12,(ROW(Z4)-1)*5,0)*1000 -> 309944.44 | Z5: 69045.9 | AA5: ='hydrogen storage'!D12 -> 2110.9935 | AB5: =(AB4+AB6)/2 -> 2.4462328 | AC5: =AB5*2 -> 4.8924656 | AD5: =(AD4+AD6)/2 -> 4.026968 | AE5: =DAC!B22 -> 329.49144
A6: 2040 | B6: =OFFSET(battery!$F$15,(ROW(B5)-1)*5,0)*1000 -> 449709.83 | C6: =OFFSET(battery!$C$15,(ROW(C5)-1)*5,0)*1000 -> 142362.74 | D6: 628000 | E6: 746000 | F6: =OFFSET(gas!$C$18,(ROW(gas!C5)-1)*5,0)*1000 -> 314962.84 | G6: =ccs!$H$6*ccs!B24 -> 164.89505 | H6: =OFFSET(gas!$F$18,(ROW(gas!E5)-1)*5,0)*1000 -> 348074.41 | I6: =ccs!$H$6*ccs!B24 -> 164.89505 | J6: =OFFSET(land!$C$12,(ROW(J5)-1)*5,0)*1000 -> 880072.15 | K6: =OFFSET(offshore!$K$13,(ROW(K5)-1)*5,0)*1000 -> 2075879.5 | L6: =OFFSET(coal!$C$20,(ROW(L5)-1)*5,0)*1000 -> 550665.03 | M6: =ccs!$C$6*ccs!B24 -> 172.07299 | N6: =OFFSET(coal!$F$20,(ROW(N5)-1)*5,0)*1000 -> 1051344.9 | O6: =ccs!$F$6*ccs!B24 -> 130.60088 | P6: =OFFSET(nuclear!$B$8,(ROW(P5)-1)*5,0)*1000 -> 1879782.7 | Q6: =5969/6.5*1000 -> 918307.69 | R6: =2240.15384615385*1000 -> 2240153.8 | S6: =SMR!T6 -> 468765.34 | T6: =ccs!$J$6*ccs!B24 -> 42.909919 | U6: =SMR!V6 -> 2894835.9 | V6: =ccs!$J$6*ccs!B24 -> 42.909919 | W6: 1245090 | X6: 1562022 | Y6: =OFFSET('H2 turbine'!$B$12,(ROW(Z5)-1)*5,0)*1000 -> 308333.33 | Z6: 69045.9 | AA6: ='hydrogen storage'!D13 -> 1811.04 | AB6: =1.93*1.1*1.0928 -> 2.3200144 | AC6: =AB6*2 -> 4.6400288 | AD6: =3.18*1.1*1.0928 -> 3.8226144 | AE6: =DAC!B23 -> 271.34589
A7: 2045 | B7: =OFFSET(battery!$F$15,(ROW(B6)-1)*5,0)*1000 -> 431425.3 | C7: =OFFSET(battery!$C$15,(ROW(C6)-1)*5,0)*1000 -> 126754.17 | D7: 628000 | E7: 746000 | F7: =OFFSET(gas!$C$18,(ROW(gas!C6)-1)*5,0)*1000 -> 300458.21 | G7: =ccs!$H$6*ccs!B25 -> 160.96898 | H7: =OFFSET(gas!$F$18,(ROW(gas!E6)-1)*5,0)*1000 -> 333130.25 | I7: =ccs!$H$6*ccs!B25 -> 160.96898 | J7: =OFFSET(land!$C$12,(ROW(J6)-1)*5,0)*1000 -> 832012.11 | K7: =OFFSET(offshore!$K$13,(ROW(K6)-1)*5,0)*1000 -> 2004930.7 | L7: =OFFSET(coal!$C$20,(ROW(L6)-1)*5,0)*1000 -> 522948.75 | M7: =ccs!$C$6*ccs!B25 -> 167.97602 | N7: =OFFSET(coal!$F$20,(ROW(N6)-1)*5,0)*1000 -> 1040624.4 | O7: =ccs!$F$6*ccs!B25 -> 127.49133 | P7: =OFFSET(nuclear!$B$8,(ROW(P6)-1)*5,0)*1000 -> 1815208.1 | Q7: =5969/6.5*1000 -> 918307.69 | R7: =2240.15384615385*1000 -> 2240153.8 | S7: =SMR!T7 -> 447177.82 | T7: =ccs!$J$6*ccs!B25 -> 41.888254 | U7: =SMR!V7 -> 2749131.9 | V7: =ccs!$J$6*ccs!B25 -> 41.888254 | W7: 1245090 | X7: 1562022 | Y7: =OFFSET('H2 turbine'!$B$12,(ROW(Z6)-1)*5,0)*1000 -> 306722.22 | Z7: 69045.9 | AA7: ='hydrogen storage'!D14 -> 1629.936 | AB7: =1.93*1.1*1.0928 -> 2.3200144 | AC7: =AB7*2 -> 4.6400288 | AD7: =3.18*1.1*1.0928 -> 3.8226144 | AE7: =DAC!B24 -> 251.96404
A8: 2050 | B8: =OFFSET(battery!$F$15,(ROW(B7)-1)*5,0)*1000 -> 412034.81 | C8: =OFFSET(battery!$C$15,(ROW(C7)-1)*5,0)*1000 -> 111278.96 | D8: 628000 | E8: 746000 | F8: =OFFSET(gas!$C$18,(ROW(gas!C7)-1)*5,0)*1000 -> 285953.58 | G8: =ccs!$H$6*ccs!B26 -> 157.0429 | H8: =OFFSET(gas!$F$18,(ROW(gas!E7)-1)*5,0)*1000 -> 318222.71 | I8: =ccs!$H$6*ccs!B26 -> 157.0429 | J8: =OFFSET(land!$C$12,(ROW(J7)-1)*5,0)*1000 -> 783952.07 | K8: =OFFSET(offshore!$K$13,(ROW(K7)-1)*5,0)*1000 -> 1946500.3 | L8: =OFFSET(coal!$C$20,(ROW(L7)-1)*5,0)*1000 -> 495210.68 | M8: =ccs!$C$6*ccs!B26 -> 163.87904 | N8: =OFFSET(coal!$F$20,(ROW(N7)-1)*5,0)*1000 -> 1029882.2 | O8: =ccs!$F$6*ccs!B26 -> 124.38179 | P8: =OFFSET(nuclear!$B$8,(ROW(P7)-1)*5,0)*1000 -> 1738729.6 | Q8: =5969/6.5*1000 -> 918307.69 | R8: =2240.15384615385*1000 -> 2240153.8 | S8: =SMR!T8 -> 425590.3 | T8: =ccs!$J$6*ccs!B26 -> 40.86659 | U8: =SMR!V8 -> 2603313.4 | V8: =ccs!$J$6*ccs!B26 -> 40.86659 | W8: 1245090 | X8: 1562022 | Y8: =OFFSET('H2 turbine'!$B$12,(ROW(Z7)-1)*5,0)*1000 -> 305111.11 | Z8: 69045.9 | AA8: ='hydrogen storage'!D15 -> 1448.832 | AB8: =1.93*1.1*1.0928 -> 2.3200144 | AC8: =AB8*2 -> 4.6400288 | AD8: =3.18*1.1*1.0928 -> 3.8226144 | AE8: =DAC!B25 -> 232.58219

Sheet High_cost_wind
A1: Vintage | B1: Battery_Storage | C1: Battery_Storage_energy | D1: Central_PV | E1: Residential_PV | F1: Gas_Combustion_Turbine | G1: Gas_Combustion_Turbine_CCS | H1: Gas_CCGT | I1: Gas_CCGT_CCS | J1: Wind | K1: Offshore_Wind | L1: Coal | M1: Coal_CCS | N1: Coal_IGCC | O1: Coal_IGCC_CCS | P1: Nuclear | Q1: Hydro_Pumped | R1: Hydro_NonPumped | S1: SMR | T1: SMR_CCS | U1: Gasification | V1: Gasification_CCS | W1: Electrolyzer | X1: Fuel_cell | Y1: Hydrogen_turbine | Z1: Tank | AA1: Salt_cavern | AB1: CCS_storage_oil | AC1: CCS_storage_saline | AD1: CCS_storage_offshore | AE1: DAC
A2: 2020 | B2: =OFFSET(battery!$F$15,(ROW(B1)-1)*5,0)*1000 -> 492307.69 | C2: =OFFSET(battery!$C$15,(ROW(C1)-1)*5,0)*1000 -> 246153.85 | D2: =OFFSET(Solar!$C$11,(ROW(D1)-1)*5,0)*1000 -> 628000 | E2: =OFFSET(Solar!$F$11,(ROW(Solar!E1)-1)*5,0)*1000 -> 746000 | F2: =OFFSET(gas!$C$18,(ROW(gas!C1)-1)*5,0)*1000 -> 367230.77 | G2: =ccs!$H$6*ccs!B20 -> 337.64225 | H2: =OFFSET(gas!$F$18,(ROW(gas!E1)-1)*5,0)*1000 -> 408913.26 | I2: =ccs!$H$6*ccs!B20 -> 337.64225 | J2: =OFFSET(land!$C$12,(ROW(J1)-1)*5,0)*1000 -> 1157000 | K2: =OFFSET(offshore!$K$13,(ROW(K1)-1)*5,0)*1000 -> 2857000 | L2: =OFFSET(coal!$C$20,(ROW(L1)-1)*5,0)*1000 -> 622461.54 | M2: =ccs!$C$6*ccs!B20 -> 352.33994 | N2: =OFFSET(coal!$F$20,(ROW(N1)-1)*5,0)*1000 -> 1089999.5 | O2: =ccs!$F$6*ccs!B20 -> 267.42084 | P2: =OFFSET(nuclear!$B$8,(ROW(P1)-1)*5,0)*1000 -> 2461538.5 | Q2: =5969/6.5*1000 -> 918307.69 | R2: =2240.15384615385*1000 -> 2240153.8 | S2: =SMR!T2 -> 546556.72 | T2: =ccs!$J$6*ccs!B20 -> 87.863168 | U2: =SMR!V2 -> 3272268.8 | V2: =ccs!$J$6*ccs!B20 -> 87.863168 | W2: =OFFSET(Electrolyzer!$C$2,(ROW(W1)-1)*5,0)*1000 -> 1245090 | X2: ='Fuel cell'!C2*1000 -> 1562022 | Y2: =OFFSET('H2 turbine'!$B$12,(ROW(Z1)-1)*5,0)*1000 -> 314777.78 | Z2: ='hydrogen storage'!B9 -> 69045.9 | AA2: ='hydrogen storage'!D9 -> 3610.761 | AB2: =2.36*1.1*1.0928 -> 2.8369088 | AC2: =AB2*2 -> 5.6738176 | AD2: =3.89*1.1*1.0928 -> 4.6760912 | AE2: =DAC!B19 -> 839.88014
A3: 2025 | B3: =OFFSET(battery!$F$15,(ROW(B2)-1)*5,0)*1000 -> 474606.98 | C3: =OFFSET(battery!$C$15,(ROW(C2)-1)*5,0)*1000 -> 219340.56 | D3: =OFFSET(Solar!$C$11,(ROW(D2)-1)*5,0)*1000 -> 607009.58 | E3: =OFFSET(Solar!$F$11,(ROW(Solar!E2)-1)*5,0)*1000 -> 686543.83 | F3: =OFFSET(gas!$C$18,(ROW(gas!C2)-1)*5,0)*1000 -> 358513.34 | G3: =ccs!$H$6*ccs!B21 -> 235.56436 | H3: =OFFSET(gas!$F$18,(ROW(gas!E2)-1)*5,0)*1000 -> 398327.81 | I3: =ccs!$H$6*ccs!B21 -> 235.56436 | J3: 1157000 | K3: 2857000 | L3: =OFFSET(coal!$C$20,(ROW(L2)-1)*5,0)*1000 -> 612285.83 | M3: =ccs!$C$6*ccs!B21 -> 245.81856 | N3: =OFFSET(coal!$F$20,(ROW(N2)-1)*5,0)*1000 -> 1083549.8 | O3: =ccs!$F$6*ccs!B21 -> 186.57268 | P3: =OFFSET(nuclear!$B$8,(ROW(P2)-1)*5,0)*1000 -> 2113664.3 | Q3: =5969/6.5*1000 -> 918307.69 | R3: =2240.15384615385*1000 -> 2240153.8 | S3: =SMR!T3 -> 533582.41 | T3: =ccs!$J$6*ccs!B21 -> 61.299884 | U3: =SMR!V3 -> 3218775.3 | V3: =ccs!$J$6*ccs!B21 -> 61.299884 | W3: 1245090 | X3: 1562022 | Y3: =OFFSET('H2 turbine'!$B$12,(ROW(Z2)-1)*5,0)*1000 -> 313166.67 | Z3: 69045.9 | AA3: ='hydrogen storage'!D10 -> 3010.854 | AB3: =2.25*1.1*1.0928 -> 2.70468 | AC3: =AB3*2 -> 5.40936 | AD3: =3.7*1.1*1.0928 -> 4.447696 | AE3: =DAC!B20 -> 620.21918
A4: 2030 | B4: =OFFSET(battery!$F$15,(ROW(B3)-1)*5,0)*1000 -> 483790.42 | C4: =OFFSET(battery!$C$15,(ROW(C3)-1)*5,0)*1000 -> 173879.95 | D4: =OFFSET(Solar!$C$11,(ROW(D3)-1)*5,0)*1000 -> 505217.02 | E4: =OFFSET(Solar!$F$11,(ROW(Solar!E3)-1)*5,0)*1000 -> 548996.6 | F4: =OFFSET(gas!$C$18,(ROW(gas!C3)-1)*5,0)*1000 -> 344008.72 | G4: =ccs!$H$6*ccs!B22 -> 196.30363 | H4: =OFFSET(gas!$F$18,(ROW(gas!E3)-1)*5,0)*1000 -> 380673.19 | I4: =ccs!$H$6*ccs!B22 -> 196.30363 | J4: 1157000 | K4: 2857000 | L4: =OFFSET(coal!$C$20,(ROW(L3)-1)*5,0)*1000 -> 595355.36 | M4: =ccs!$C$6*ccs!B22 -> 204.8488 | N4: =OFFSET(coal!$F$20,(ROW(N3)-1)*5,0)*1000 -> 1072807.6 | O4: =ccs!$F$6*ccs!B22 -> 155.47723 | P4: =OFFSET(nuclear!$B$8,(ROW(P3)-1)*5,0)*1000 -> 2015508 | Q4: =5969/6.5*1000 -> 918307.69 | R4: =2240.15384615385*1000 -> 2240153.8 | S4: =SMR!T4 -> 511994.89 | T4: =ccs!$J$6*ccs!B22 -> 51.083237 | U4: =SMR!V4 -> 3129772.1 | V4: =ccs!$J$6*ccs!B22 -> 51.083237 | W4: 1245090 | X4: 1562022 | Y4: =OFFSET('H2 turbine'!$B$12,(ROW(Z3)-1)*5,0)*1000 -> 311555.56 | Z4: 69045.9 | AA4: ='hydrogen storage'!D11 -> 2410.947 | AB4: =2.14*1.1*1.0928 -> 2.5724512 | AC4: =AB4*2 -> 5.1449024 | AD4: =3.52*1.1*1.0928 -> 4.2313216 | AE4: =DAC!B21 -> 387.63699
A5: 2035 | B5: =OFFSET(battery!$F$15,(ROW(B4)-1)*5,0)*1000 -> 467109.57 | C5: =OFFSET(battery!$C$15,(ROW(C4)-1)*5,0)*1000 -> 158078 | D5: =OFFSET(Solar!$C$11,(ROW(D4)-1)*5,0)*1000 -> 403424.47 | E5: =OFFSET(Solar!$F$11,(ROW(Solar!E4)-1)*5,0)*1000 -> 411449.37 | F5: =OFFSET(gas!$C$18,(ROW(gas!C4)-1)*5,0)*1000 -> 329504.09 | G5: =ccs!$H$6*ccs!B23 -> 180.59934 | H5: =OFFSET(gas!$F$18,(ROW(gas!E4)-1)*5,0)*1000 -> 363018.57 | I5: =ccs!$H$6*ccs!B23 -> 180.59934 | J5: 1157000 | K5: 2857000 | L5: =OFFSET(coal!$C$20,(ROW(L4)-1)*5,0)*1000 -> 578403.11 | M5: =ccs!$C$6*ccs!B23 -> 188.4609 | N5: =OFFSET(coal!$F$20,(ROW(N4)-1)*5,0)*1000 -> 1062087.1 | O5: =ccs!$F$6*ccs!B23 -> 143.03906 | P5: =OFFSET(nuclear!$B$8,(ROW(P4)-1)*5,0)*1000 -> 1948571.2 | Q5: =5969/6.5*1000 -> 918307.69 | R5: =2240.15384615385*1000 -> 2240153.8 | S5: =SMR!T5 -> 490407.37 | T5: =ccs!$J$6*ccs!B23 -> 46.996578 | U5: =SMR!V5 -> 3040654.4 | V5: =ccs!$J$6*ccs!B23 -> 46.996578 | W5: 1245090 | X5: 1562022 | Y5: =OFFSET('H2 turbine'!$B$12,(ROW(Z4)-1)*5,0)*1000 -> 309944.44 | Z5: 69045.9 | AA5: ='hydrogen storage'!D12 -> 2110.9935 | AB5: =(AB4+AB6)/2 -> 2.4462328 | AC5: =AB5*2 -> 4.8924656 | AD5: =(AD4+AD6)/2 -> 4.026968 | AE5: =DAC!B22 -> 329.49144
A6: 2040 | B6: =OFFSET(battery!$F$15,(ROW(B5)-1)*5,0)*1000 -> 449709.83 | C6: =OFFSET(battery!$C$15,(ROW(C5)-1)*5,0)*1000 -> 142362.74 | D6: =OFFSET(Solar!$C$11,(ROW(D5)-1)*5,0)*1000 -> 371518.84 | E6: =OFFSET(Solar!$F$11,(ROW(Solar!E5)-1)*5,0)*1000 -> 371597.4 | F6: =OFFSET(gas!$C$18,(ROW(gas!C5)-1)*5,0)*1000 -> 314962.84 | G6: =ccs!$H$6*ccs!B24 -> 164.89505 | H6: =OFFSET(gas!$F$18,(ROW(gas!E5)-1)*5,0)*1000 -> 348074.41 | I6: =ccs!$H$6*ccs!B24 -> 164.89505 | J6: 1157000 | K6: 2857000 | L6: =OFFSET(coal!$C$20,(ROW(L5)-1)*5,0)*1000 -> 550665.03 | M6: =ccs!$C$6*ccs!B24 -> 172.07299 | N6: =OFFSET(coal!$F$20,(ROW(N5)-1)*5,0)*1000 -> 1051344.9 | O6: =ccs!$F$6*ccs!B24 -> 130.60088 | P6: =OFFSET(nuclear!$B$8,(ROW(P5)-1)*5,0)*1000 -> 1879782.7 | Q6: =5969/6.5*1000 -> 918307.69 | R6: =2240.15384615385*1000 -> 2240153.8 | S6: =SMR!T6 -> 468765.34 | T6: =ccs!$J$6*ccs!B24 -> 42.909919 | U6: =SMR!V6 -> 2894835.9 | V6: =ccs!$J$6*ccs!B24 -> 42.909919 | W6: 1245090 | X6: 1562022 | Y6: =OFFSET('H2 turbine'!$B$12,(ROW(Z5)-1)*5,0)*1000 -> 308333.33 | Z6: 69045.9 | AA6: ='hydrogen storage'!D13 -> 1811.04 | AB6: =1.93*1.1*1.0928 -> 2.3200144 | AC6: =AB6*2 -> 4.6400288 | AD6: =3.18*1.1*1.0928 -> 3.8226144 | AE6: =DAC!B23 -> 271.34589
